2017-09-05 10:34:03,875 [Thread-4:17148] [django.request:170] [WARNING]- Not Found: /company_influence/weibo_2/
2017-09-05 10:34:22,026 [Thread-5:13116] [django.request:170] [WARNING]- Not Found: /
2017-09-05 10:35:03,000 [Thread-6:16444] [django.request:170] [WARNING]- Not Found: /
2017-09-05 10:38:17,884 [Thread-4:11292] [django.request:170] [WARNING]- Not Found: /
2017-09-05 10:38:33,627 [Thread-6:952] [django.request:170] [WARNING]- Not Found: /company_influence
2017-09-05 10:39:05,806 [Thread-9:15088] [django.request:256] [ERROR]- Internal Server Error: /company_influence/company_official_influence_2/
Traceback (most recent call last):
  File "D:\python27\lib\site-packages\django\core\handlers\base.py", line 132, in get_response
    response = wrapped_callback(request, *callback_args, **callback_kwargs)
  File "D:\zhujianwei\sem_analysis\company_influence\views.py", line 42, in company_official_influence
    return JsonResponse(news_count_dict)
  File "D:\python27\lib\site-packages\django\http\response.py", line 535, in __init__
    data = json.dumps(data, cls=encoder)
  File "D:\python27\lib\json\__init__.py", line 251, in dumps
    sort_keys=sort_keys, **kw).encode(obj)
  File "D:\python27\lib\json\encoder.py", line 207, in encode
    chunks = self.iterencode(o, _one_shot=True)
  File "D:\python27\lib\json\encoder.py", line 270, in iterencode
    return _iterencode(o, 0)
  File "D:\python27\lib\site-packages\django\core\serializers\json.py", line 115, in default
    return super(DjangoJSONEncoder, self).default(o)
  File "D:\python27\lib\json\encoder.py", line 184, in default
    raise TypeError(repr(o) + " is not JSON serializable")
TypeError: <pymongo.cursor.Cursor object at 0x000000000447AB00> is not JSON serializable
2017-09-05 10:52:28,548 [Thread-2:16484] [django.request:256] [ERROR]- Internal Server Error: /company_influence/company_official_influence_2/
Traceback (most recent call last):
  File "D:\python27\lib\site-packages\django\core\handlers\base.py", line 132, in get_response
    response = wrapped_callback(request, *callback_args, **callback_kwargs)
  File "D:\zhujianwei\sem_analysis\company_influence\views.py", line 42, in company_official_influence
    return JsonResponse(news_count_dict)
  File "D:\python27\lib\site-packages\django\http\response.py", line 535, in __init__
    data = json.dumps(data, cls=encoder)
  File "D:\python27\lib\json\__init__.py", line 251, in dumps
    sort_keys=sort_keys, **kw).encode(obj)
  File "D:\python27\lib\json\encoder.py", line 207, in encode
    chunks = self.iterencode(o, _one_shot=True)
  File "D:\python27\lib\json\encoder.py", line 270, in iterencode
    return _iterencode(o, 0)
  File "D:\python27\lib\site-packages\django\core\serializers\json.py", line 115, in default
    return super(DjangoJSONEncoder, self).default(o)
  File "D:\python27\lib\json\encoder.py", line 184, in default
    raise TypeError(repr(o) + " is not JSON serializable")
TypeError: <pymongo.cursor.Cursor object at 0x0000000004702B70> is not JSON serializable
2017-09-05 10:53:55,526 [Thread-2:7508] [django.request:256] [ERROR]- Internal Server Error: /company_influence/company_official_influence_2/
Traceback (most recent call last):
  File "D:\python27\lib\site-packages\django\core\handlers\base.py", line 132, in get_response
    response = wrapped_callback(request, *callback_args, **callback_kwargs)
  File "D:\zhujianwei\sem_analysis\company_influence\views.py", line 42, in company_official_influence
    return JsonResponse(news_count_dict)
  File "D:\python27\lib\site-packages\django\http\response.py", line 535, in __init__
    data = json.dumps(data, cls=encoder)
  File "D:\python27\lib\json\__init__.py", line 251, in dumps
    sort_keys=sort_keys, **kw).encode(obj)
  File "D:\python27\lib\json\encoder.py", line 207, in encode
    chunks = self.iterencode(o, _one_shot=True)
  File "D:\python27\lib\json\encoder.py", line 270, in iterencode
    return _iterencode(o, 0)
  File "D:\python27\lib\site-packages\django\core\serializers\json.py", line 115, in default
    return super(DjangoJSONEncoder, self).default(o)
  File "D:\python27\lib\json\encoder.py", line 184, in default
    raise TypeError(repr(o) + " is not JSON serializable")
TypeError: <pymongo.cursor.Cursor object at 0x0000000004478BA8> is not JSON serializable
2017-09-05 14:02:46,082 [Thread-2:7364] [django.request:256] [ERROR]- Internal Server Error: /company_influence/company_official_influence_2/
Traceback (most recent call last):
  File "D:\python27\lib\site-packages\django\core\handlers\base.py", line 132, in get_response
    response = wrapped_callback(request, *callback_args, **callback_kwargs)
  File "D:\zhujianwei\sem_analysis\company_influence\views.py", line 41, in company_official_influence
    end_time=end_time)
  File "D:\zhujianwei\sem_analysis\common\source_media.py", line 166, in get_news_count
    news_count = self._get_news(data_source_id_list, start_time=start_time, end_time=end_time)
  File "D:\zhujianwei\sem_analysis\common\source_media.py", line 221, in _get_news
    sort_news_objects_serialize = serialize_news_obj(sort_news_objects)
  File "D:\zhujianwei\sem_analysis\common\common.py", line 54, in serialize_news_obj
    for item in news_obj:
  File "D:\python27\lib\site-packages\pymongo\cursor.py", line 1114, in next
    if len(self.__data) or self._refresh():
  File "D:\python27\lib\site-packages\pymongo\cursor.py", line 1036, in _refresh
    self.__collation))
  File "D:\python27\lib\site-packages\pymongo\cursor.py", line 928, in __send_message
    helpers._check_command_response(doc['data'][0])
  File "D:\python27\lib\site-packages\pymongo\helpers.py", line 205, in _check_command_response
    raise ExecutionTimeout(errmsg, code, response)
ExecutionTimeout: Operation timed out
2017-09-05 14:14:30,441 [Thread-13:11588] [django.request:170] [WARNING]- Not Found: /company_influence
2017-09-05 14:14:33,351 [Thread-14:11716] [django.request:170] [WARNING]- Not Found: /company_influence
2017-09-05 14:14:47,816 [Thread-17:12568] [django.request:170] [WARNING]- Not Found: /product_influence
2017-09-05 14:15:09,865 [Thread-19:1548] [django.request:170] [WARNING]- Not Found: /product_influence
2017-09-05 14:15:20,970 [Thread-21:16140] [django.request:170] [WARNING]- Not Found: /product_influence/product_information_influence
2017-09-05 14:17:03,943 [Thread-26:15124] [django.request:256] [ERROR]- Internal Server Error: /product_influence/product_weibo_user_location_2/
Traceback (most recent call last):
  File "D:\python27\lib\site-packages\django\core\handlers\base.py", line 230, in get_response
    response = self.apply_response_fixes(request, response)
  File "D:\python27\lib\site-packages\django\core\handlers\base.py", line 277, in apply_response_fixes
    response = func(request, response)
  File "D:\python27\lib\site-packages\django\http\utils.py", line 30, in conditional_content_removal
    if 100 <= response.status_code < 200 or response.status_code in (204, 304):
AttributeError: 'dict' object has no attribute 'status_code'
2017-09-05 14:32:39,625 [Thread-28:4316] [django.request:256] [ERROR]- Internal Server Error: /product_influence/product_weibo_user_location_2/
Traceback (most recent call last):
  File "D:\python27\lib\site-packages\django\core\handlers\base.py", line 230, in get_response
    response = self.apply_response_fixes(request, response)
  File "D:\python27\lib\site-packages\django\core\handlers\base.py", line 277, in apply_response_fixes
    response = func(request, response)
  File "D:\python27\lib\site-packages\django\http\utils.py", line 30, in conditional_content_removal
    if 100 <= response.status_code < 200 or response.status_code in (204, 304):
AttributeError: 'dict' object has no attribute 'status_code'
2017-09-05 15:26:03,344 [Thread-2:12332] [django.request:256] [ERROR]- Internal Server Error: /product_influence/product_weibo_user_location_2/
Traceback (most recent call last):
  File "D:\python27\lib\site-packages\django\core\handlers\base.py", line 230, in get_response
    response = self.apply_response_fixes(request, response)
  File "D:\python27\lib\site-packages\django\core\handlers\base.py", line 277, in apply_response_fixes
    response = func(request, response)
  File "D:\python27\lib\site-packages\django\http\utils.py", line 30, in conditional_content_removal
    if 100 <= response.status_code < 200 or response.status_code in (204, 304):
AttributeError: 'dict' object has no attribute 'status_code'
2017-09-05 16:09:59,673 [Thread-8:3692] [django.request:256] [ERROR]- Internal Server Error: /event_influence/event_influence_overview_3/
Traceback (most recent call last):
  File "D:\python27\lib\site-packages\django\core\handlers\base.py", line 132, in get_response
    response = wrapped_callback(request, *callback_args, **callback_kwargs)
  File "D:\zhujianwei\sem_analysis\event_influence\views.py", line 25, in event_influence_overview
    data_source_id_list)["seven_sentiment_influence_dict"]
  File "D:\zhujianwei\sem_analysis\common\source_media.py", line 71, in get_sentiment_influence
    sentiment=sentiment)['influence']
  File "D:\zhujianwei\sem_analysis\common\source_media.py", line 355, in _get_news
    news_count = news_objects.count()
  File "D:\python27\lib\site-packages\pymongo\cursor.py", line 711, in count
    return self.__collection._count(cmd, self.__collation)
  File "D:\python27\lib\site-packages\pymongo\collection.py", line 1310, in _count
    collation=collation)
  File "D:\python27\lib\site-packages\pymongo\collection.py", line 232, in _command
    collation=collation)
  File "D:\python27\lib\site-packages\pymongo\pool.py", line 419, in command
    collation=collation)
  File "D:\python27\lib\site-packages\pymongo\network.py", line 116, in command
    parse_write_concern_error=parse_write_concern_error)
  File "D:\python27\lib\site-packages\pymongo\helpers.py", line 210, in _check_command_response
    raise OperationFailure(msg % errmsg, code, response)
OperationFailure: failed on : shard1RS
2017-09-06 09:38:39,670 [Thread-2:10208] [django.request:256] [ERROR]- Internal Server Error: /sem_index/weibo_2/
Traceback (most recent call last):
  File "D:\python27\lib\site-packages\django\core\handlers\base.py", line 132, in get_response
    response = wrapped_callback(request, *callback_args, **callback_kwargs)
  File "D:\zhujianwei\sem_analysis\sem_index\views.py", line 118, in weibo
    weibo_obj = weibo_instance.get_sort_news_objects(data_source_id_list)["today_sort_news_objects"].limit(10)
AttributeError: 'list' object has no attribute 'limit'
2017-09-06 09:38:40,035 [Thread-3:15016] [django.request:170] [WARNING]- Not Found: /favicon.ico
2017-09-06 09:44:01,309 [Thread-2:7960] [django.request:256] [ERROR]- Internal Server Error: /sem_index/weibo_2/
Traceback (most recent call last):
  File "D:\python27\lib\site-packages\django\core\handlers\base.py", line 132, in get_response
    response = wrapped_callback(request, *callback_args, **callback_kwargs)
  File "D:\zhujianwei\sem_analysis\sem_index\views.py", line 118, in weibo
    weibo_obj = weibo_instance.get_sort_news_objects(data_source_id_list)["today_sort_news_objects"].limit(10)
  File "D:\python27\lib\site-packages\pymongo\cursor.py", line 401, in limit
    self.__check_okay_to_chain()
  File "D:\python27\lib\site-packages\pymongo\cursor.py", line 345, in __check_okay_to_chain
    raise InvalidOperation("cannot set options after executing query")
InvalidOperation: cannot set options after executing query
2017-09-06 09:54:40,361 [Thread-2:11892] [django.request:256] [ERROR]- Internal Server Error: /sem_index/weibo_2/
Traceback (most recent call last):
  File "D:\python27\lib\site-packages\django\core\handlers\base.py", line 132, in get_response
    response = wrapped_callback(request, *callback_args, **callback_kwargs)
  File "D:\zhujianwei\sem_analysis\sem_index\views.py", line 118, in weibo
    weibo_obj = weibo_instance.get_sort_news_objects(data_source_id_list)["today_sort_news_objects"].limit(10)
  File "D:\zhujianwei\sem_analysis\common\source_media.py", line 154, in get_sort_news_objects
    end_time="2017-01-03 19:20:00")["sort_news_objects"]}
KeyError: 'sort_news_objects'
2017-09-06 09:56:31,119 [Thread-2:13896] [django.request:256] [ERROR]- Internal Server Error: /sem_index/weibo_2/
Traceback (most recent call last):
  File "D:\python27\lib\site-packages\django\core\handlers\base.py", line 132, in get_response
    response = wrapped_callback(request, *callback_args, **callback_kwargs)
  File "D:\zhujianwei\sem_analysis\sem_index\views.py", line 118, in weibo
    weibo_obj = weibo_instance.get_sort_news_objects(data_source_id_list)["today_sort_news_objects"].limit(10)
  File "D:\python27\lib\site-packages\pymongo\cursor.py", line 401, in limit
    self.__check_okay_to_chain()
  File "D:\python27\lib\site-packages\pymongo\cursor.py", line 345, in __check_okay_to_chain
    raise InvalidOperation("cannot set options after executing query")
InvalidOperation: cannot set options after executing query
2017-09-06 10:02:55,490 [Thread-2:9296] [django.request:256] [ERROR]- Internal Server Error: /sem_index/weibo_2/
Traceback (most recent call last):
  File "D:\python27\lib\site-packages\django\core\handlers\base.py", line 132, in get_response
    response = wrapped_callback(request, *callback_args, **callback_kwargs)
  File "D:\zhujianwei\sem_analysis\sem_index\views.py", line 118, in weibo
    weibo_obj = weibo_instance.get_sort_news_objects(data_source_id_list)["today_sort_news_objects"].limit(10)
  File "D:\python27\lib\site-packages\pymongo\cursor.py", line 401, in limit
    self.__check_okay_to_chain()
  File "D:\python27\lib\site-packages\pymongo\cursor.py", line 345, in __check_okay_to_chain
    raise InvalidOperation("cannot set options after executing query")
InvalidOperation: cannot set options after executing query
2017-09-06 10:03:26,243 [Thread-3:17124] [django.request:256] [ERROR]- Internal Server Error: /sem_index/weibo_2/
Traceback (most recent call last):
  File "D:\python27\lib\site-packages\django\core\handlers\base.py", line 132, in get_response
    response = wrapped_callback(request, *callback_args, **callback_kwargs)
  File "D:\zhujianwei\sem_analysis\sem_index\views.py", line 118, in weibo
    weibo_obj = weibo_instance.get_sort_news_objects(data_source_id_list)["today_sort_news_objects"].limit(10)
  File "D:\python27\lib\site-packages\pymongo\cursor.py", line 401, in limit
    self.__check_okay_to_chain()
  File "D:\python27\lib\site-packages\pymongo\cursor.py", line 345, in __check_okay_to_chain
    raise InvalidOperation("cannot set options after executing query")
InvalidOperation: cannot set options after executing query
2017-09-06 10:06:42,805 [Thread-2:7984] [django.request:256] [ERROR]- Internal Server Error: /sem_index/weibo_2/
Traceback (most recent call last):
  File "D:\python27\lib\site-packages\django\core\handlers\base.py", line 132, in get_response
    response = wrapped_callback(request, *callback_args, **callback_kwargs)
  File "D:\zhujianwei\sem_analysis\sem_index\views.py", line 118, in weibo
    weibo_obj = weibo_instance.get_sort_news_objects(data_source_id_list)["today_sort_news_objects"].limit(10)
  File "D:\python27\lib\site-packages\pymongo\cursor.py", line 401, in limit
    self.__check_okay_to_chain()
  File "D:\python27\lib\site-packages\pymongo\cursor.py", line 345, in __check_okay_to_chain
    raise InvalidOperation("cannot set options after executing query")
InvalidOperation: cannot set options after executing query
2017-09-06 10:07:50,207 [Thread-2:7208] [django.request:256] [ERROR]- Internal Server Error: /sem_index/weibo_2/
Traceback (most recent call last):
  File "D:\python27\lib\site-packages\django\core\handlers\base.py", line 132, in get_response
    response = wrapped_callback(request, *callback_args, **callback_kwargs)
  File "D:\zhujianwei\sem_analysis\sem_index\views.py", line 118, in weibo
    weibo_obj = weibo_instance.get_sort_news_objects(data_source_id_list)["today_sort_news_objects"].limit(10)
  File "D:\python27\lib\site-packages\pymongo\cursor.py", line 401, in limit
    self.__check_okay_to_chain()
  File "D:\python27\lib\site-packages\pymongo\cursor.py", line 345, in __check_okay_to_chain
    raise InvalidOperation("cannot set options after executing query")
InvalidOperation: cannot set options after executing query
2017-09-06 10:08:22,138 [Thread-2:4916] [django.request:256] [ERROR]- Internal Server Error: /sem_index/weibo_2/
Traceback (most recent call last):
  File "D:\python27\lib\site-packages\django\core\handlers\base.py", line 132, in get_response
    response = wrapped_callback(request, *callback_args, **callback_kwargs)
  File "D:\zhujianwei\sem_analysis\sem_index\views.py", line 118, in weibo
    weibo_obj = weibo_instance.get_sort_news_objects(data_source_id_list)["today_sort_news_objects"].limit(10)
  File "D:\zhujianwei\sem_analysis\common\source_media.py", line 156, in get_sort_news_objects
    print "::::", contents["today_sort_news_objects"].limit(1)
  File "D:\python27\lib\site-packages\pymongo\cursor.py", line 401, in limit
    self.__check_okay_to_chain()
  File "D:\python27\lib\site-packages\pymongo\cursor.py", line 345, in __check_okay_to_chain
    raise InvalidOperation("cannot set options after executing query")
InvalidOperation: cannot set options after executing query
2017-09-06 10:08:44,410 [Thread-2:3348] [django.request:256] [ERROR]- Internal Server Error: /sem_index/weibo_2/
Traceback (most recent call last):
  File "D:\python27\lib\site-packages\django\core\handlers\base.py", line 132, in get_response
    response = wrapped_callback(request, *callback_args, **callback_kwargs)
  File "D:\zhujianwei\sem_analysis\sem_index\views.py", line 118, in weibo
    weibo_obj = weibo_instance.get_sort_news_objects(data_source_id_list)["today_sort_news_objects"].limit(10)
  File "D:\zhujianwei\sem_analysis\common\source_media.py", line 156, in get_sort_news_objects
    print "::::", contents["today_sort_news_objects"][0]
  File "D:\python27\lib\site-packages\pymongo\cursor.py", line 534, in __getitem__
    self.__check_okay_to_chain()
  File "D:\python27\lib\site-packages\pymongo\cursor.py", line 345, in __check_okay_to_chain
    raise InvalidOperation("cannot set options after executing query")
InvalidOperation: cannot set options after executing query
2017-09-06 10:10:42,604 [Thread-2:4596] [django.request:256] [ERROR]- Internal Server Error: /sem_index/weibo_2/
Traceback (most recent call last):
  File "D:\python27\lib\site-packages\django\core\handlers\base.py", line 132, in get_response
    response = wrapped_callback(request, *callback_args, **callback_kwargs)
  File "D:\zhujianwei\sem_analysis\sem_index\views.py", line 118, in weibo
    weibo_obj = weibo_instance.get_sort_news_objects(data_source_id_list)["today_sort_news_objects"].limit(10)
  File "D:\python27\lib\site-packages\pymongo\cursor.py", line 401, in limit
    self.__check_okay_to_chain()
  File "D:\python27\lib\site-packages\pymongo\cursor.py", line 345, in __check_okay_to_chain
    raise InvalidOperation("cannot set options after executing query")
InvalidOperation: cannot set options after executing query
2017-09-06 10:15:22,576 [Thread-2:11112] [django.request:256] [ERROR]- Internal Server Error: /sem_index/weibo_2/
Traceback (most recent call last):
  File "D:\python27\lib\site-packages\django\core\handlers\base.py", line 132, in get_response
    response = wrapped_callback(request, *callback_args, **callback_kwargs)
  File "D:\zhujianwei\sem_analysis\sem_index\views.py", line 118, in weibo
    weibo_obj = weibo_instance.get_sort_news_objects(data_source_id_list)["today_sort_news_objects"].limit(10)
  File "D:\python27\lib\site-packages\pymongo\cursor.py", line 401, in limit
    self.__check_okay_to_chain()
  File "D:\python27\lib\site-packages\pymongo\cursor.py", line 345, in __check_okay_to_chain
    raise InvalidOperation("cannot set options after executing query")
InvalidOperation: cannot set options after executing query
2017-09-06 10:15:51,398 [Thread-2:9280] [django.request:256] [ERROR]- Internal Server Error: /sem_index/weibo_2/
Traceback (most recent call last):
  File "D:\python27\lib\site-packages\django\core\handlers\base.py", line 132, in get_response
    response = wrapped_callback(request, *callback_args, **callback_kwargs)
  File "D:\zhujianwei\sem_analysis\sem_index\views.py", line 118, in weibo
    weibo_obj = weibo_instance.get_sort_news_objects(data_source_id_list)["today_sort_news_objects"].limit(10)
  File "D:\python27\lib\site-packages\pymongo\cursor.py", line 401, in limit
    self.__check_okay_to_chain()
  File "D:\python27\lib\site-packages\pymongo\cursor.py", line 345, in __check_okay_to_chain
    raise InvalidOperation("cannot set options after executing query")
InvalidOperation: cannot set options after executing query
2017-09-06 10:16:29,463 [Thread-2:4300] [django.request:256] [ERROR]- Internal Server Error: /sem_index/weibo_2/
Traceback (most recent call last):
  File "D:\python27\lib\site-packages\django\core\handlers\base.py", line 132, in get_response
    response = wrapped_callback(request, *callback_args, **callback_kwargs)
  File "D:\zhujianwei\sem_analysis\sem_index\views.py", line 118, in weibo
    weibo_obj = weibo_instance.get_sort_news_objects(data_source_id_list)["today_sort_news_objects"].limit(10)
  File "D:\python27\lib\site-packages\pymongo\cursor.py", line 401, in limit
    self.__check_okay_to_chain()
  File "D:\python27\lib\site-packages\pymongo\cursor.py", line 345, in __check_okay_to_chain
    raise InvalidOperation("cannot set options after executing query")
InvalidOperation: cannot set options after executing query
2017-09-06 10:16:50,247 [Thread-2:10640] [django.request:256] [ERROR]- Internal Server Error: /sem_index/weibo_2/
Traceback (most recent call last):
  File "D:\python27\lib\site-packages\django\core\handlers\base.py", line 132, in get_response
    response = wrapped_callback(request, *callback_args, **callback_kwargs)
  File "D:\zhujianwei\sem_analysis\sem_index\views.py", line 118, in weibo
    weibo_obj = weibo_instance.get_sort_news_objects(data_source_id_list)["today_sort_news_objects"].limit(10)
  File "D:\python27\lib\site-packages\pymongo\cursor.py", line 401, in limit
    self.__check_okay_to_chain()
  File "D:\python27\lib\site-packages\pymongo\cursor.py", line 345, in __check_okay_to_chain
    raise InvalidOperation("cannot set options after executing query")
InvalidOperation: cannot set options after executing query
2017-09-06 10:17:37,808 [Thread-2:14948] [django.request:256] [ERROR]- Internal Server Error: /sem_index/weibo_2/
Traceback (most recent call last):
  File "D:\python27\lib\site-packages\django\core\handlers\base.py", line 132, in get_response
    response = wrapped_callback(request, *callback_args, **callback_kwargs)
  File "D:\zhujianwei\sem_analysis\sem_index\views.py", line 118, in weibo
    weibo_obj = weibo_instance.get_sort_news_objects(data_source_id_list)["today_sort_news_objects"].limit(10)
  File "D:\python27\lib\site-packages\pymongo\cursor.py", line 401, in limit
    self.__check_okay_to_chain()
  File "D:\python27\lib\site-packages\pymongo\cursor.py", line 345, in __check_okay_to_chain
    raise InvalidOperation("cannot set options after executing query")
InvalidOperation: cannot set options after executing query
2017-09-06 10:17:54,976 [Thread-2:10956] [django.request:256] [ERROR]- Internal Server Error: /sem_index/weibo_2/
Traceback (most recent call last):
  File "D:\python27\lib\site-packages\django\core\handlers\base.py", line 132, in get_response
    response = wrapped_callback(request, *callback_args, **callback_kwargs)
  File "D:\zhujianwei\sem_analysis\sem_index\views.py", line 118, in weibo
    weibo_obj = weibo_instance.get_sort_news_objects(data_source_id_list)["today_sort_news_objects"].limit(10)
  File "D:\zhujianwei\sem_analysis\common\source_media.py", line 154, in get_sort_news_objects
    end_time="2017-01-03 19:20:00")["sort_news_objects"]}
  File "D:\zhujianwei\sem_analysis\common\source_media.py", line 390, in _get_news
    print len(contents["news_objects"])
TypeError: object of type 'Cursor' has no len()
2017-09-06 10:18:23,869 [Thread-2:1620] [django.request:256] [ERROR]- Internal Server Error: /sem_index/weibo_2/
Traceback (most recent call last):
  File "D:\python27\lib\site-packages\django\core\handlers\base.py", line 132, in get_response
    response = wrapped_callback(request, *callback_args, **callback_kwargs)
  File "D:\zhujianwei\sem_analysis\sem_index\views.py", line 118, in weibo
    weibo_obj = weibo_instance.get_sort_news_objects(data_source_id_list)["today_sort_news_objects"].limit(10)
  File "D:\python27\lib\site-packages\pymongo\cursor.py", line 401, in limit
    self.__check_okay_to_chain()
  File "D:\python27\lib\site-packages\pymongo\cursor.py", line 345, in __check_okay_to_chain
    raise InvalidOperation("cannot set options after executing query")
InvalidOperation: cannot set options after executing query
2017-09-06 10:18:49,565 [Thread-2:7752] [django.request:256] [ERROR]- Internal Server Error: /sem_index/weibo_2/
Traceback (most recent call last):
  File "D:\python27\lib\site-packages\django\core\handlers\base.py", line 132, in get_response
    response = wrapped_callback(request, *callback_args, **callback_kwargs)
  File "D:\zhujianwei\sem_analysis\sem_index\views.py", line 118, in weibo
    weibo_obj = weibo_instance.get_sort_news_objects(data_source_id_list)["today_sort_news_objects"].limit(10)
  File "D:\zhujianwei\sem_analysis\common\source_media.py", line 154, in get_sort_news_objects
    end_time="2017-01-03 19:20:00")["sort_news_objects"]}
  File "D:\zhujianwei\sem_analysis\common\source_media.py", line 390, in _get_news
    print contents["news_objects"].limit(1)
  File "D:\python27\lib\site-packages\pymongo\cursor.py", line 401, in limit
    self.__check_okay_to_chain()
  File "D:\python27\lib\site-packages\pymongo\cursor.py", line 345, in __check_okay_to_chain
    raise InvalidOperation("cannot set options after executing query")
InvalidOperation: cannot set options after executing query
2017-09-06 10:19:47,023 [Thread-2:16272] [django.request:256] [ERROR]- Internal Server Error: /sem_index/weibo_2/
Traceback (most recent call last):
  File "D:\python27\lib\site-packages\django\core\handlers\base.py", line 132, in get_response
    response = wrapped_callback(request, *callback_args, **callback_kwargs)
  File "D:\zhujianwei\sem_analysis\sem_index\views.py", line 118, in weibo
    weibo_obj = weibo_instance.get_sort_news_objects(data_source_id_list)["today_sort_news_objects"].limit(10)
  File "D:\python27\lib\site-packages\pymongo\cursor.py", line 401, in limit
    self.__check_okay_to_chain()
  File "D:\python27\lib\site-packages\pymongo\cursor.py", line 345, in __check_okay_to_chain
    raise InvalidOperation("cannot set options after executing query")
InvalidOperation: cannot set options after executing query
2017-09-06 10:20:05,131 [Thread-2:16172] [django.request:256] [ERROR]- Internal Server Error: /sem_index/weibo_2/
Traceback (most recent call last):
  File "D:\python27\lib\site-packages\django\core\handlers\base.py", line 132, in get_response
    response = wrapped_callback(request, *callback_args, **callback_kwargs)
  File "D:\zhujianwei\sem_analysis\sem_index\views.py", line 118, in weibo
    weibo_obj = weibo_instance.get_sort_news_objects(data_source_id_list)["today_sort_news_objects"].limit(10)
  File "D:\zhujianwei\sem_analysis\common\source_media.py", line 154, in get_sort_news_objects
    end_time="2017-01-03 19:20:00")["sort_news_objects"]}
  File "D:\zhujianwei\sem_analysis\common\source_media.py", line 390, in _get_news
    print contents["news_objects"].limit(1)
  File "D:\python27\lib\site-packages\pymongo\cursor.py", line 401, in limit
    self.__check_okay_to_chain()
  File "D:\python27\lib\site-packages\pymongo\cursor.py", line 345, in __check_okay_to_chain
    raise InvalidOperation("cannot set options after executing query")
InvalidOperation: cannot set options after executing query
2017-09-06 10:20:16,576 [Thread-4:18076] [django.request:256] [ERROR]- Internal Server Error: /sem_index/weibo_2/
Traceback (most recent call last):
  File "D:\python27\lib\site-packages\django\core\handlers\base.py", line 132, in get_response
    response = wrapped_callback(request, *callback_args, **callback_kwargs)
  File "D:\zhujianwei\sem_analysis\sem_index\views.py", line 118, in weibo
    weibo_obj = weibo_instance.get_sort_news_objects(data_source_id_list)["today_sort_news_objects"].limit(10)
  File "D:\zhujianwei\sem_analysis\common\source_media.py", line 154, in get_sort_news_objects
    end_time="2017-01-03 19:20:00")["sort_news_objects"]}
  File "D:\zhujianwei\sem_analysis\common\source_media.py", line 390, in _get_news
    print contents["news_objects"].limit(1)
  File "D:\python27\lib\site-packages\pymongo\cursor.py", line 401, in limit
    self.__check_okay_to_chain()
  File "D:\python27\lib\site-packages\pymongo\cursor.py", line 345, in __check_okay_to_chain
    raise InvalidOperation("cannot set options after executing query")
InvalidOperation: cannot set options after executing query
2017-09-06 10:20:53,026 [Thread-2:9272] [django.request:256] [ERROR]- Internal Server Error: /sem_index/weibo_2/
Traceback (most recent call last):
  File "D:\python27\lib\site-packages\django\core\handlers\base.py", line 132, in get_response
    response = wrapped_callback(request, *callback_args, **callback_kwargs)
  File "D:\zhujianwei\sem_analysis\sem_index\views.py", line 118, in weibo
    weibo_obj = weibo_instance.get_sort_news_objects(data_source_id_list)["today_sort_news_objects"].limit(10)
  File "D:\zhujianwei\sem_analysis\common\source_media.py", line 154, in get_sort_news_objects
    end_time="2017-01-03 19:20:00")["sort_news_objects"]}
  File "D:\zhujianwei\sem_analysis\common\source_media.py", line 390, in _get_news
    print '========锛?, contents["news_objects"].limit(1)
  File "D:\python27\lib\site-packages\pymongo\cursor.py", line 401, in limit
    self.__check_okay_to_chain()
  File "D:\python27\lib\site-packages\pymongo\cursor.py", line 345, in __check_okay_to_chain
    raise InvalidOperation("cannot set options after executing query")
InvalidOperation: cannot set options after executing query
2017-09-06 10:20:56,565 [Thread-3:4816] [django.request:256] [ERROR]- Internal Server Error: /sem_index/weibo_2/
Traceback (most recent call last):
  File "D:\python27\lib\site-packages\django\core\handlers\base.py", line 132, in get_response
    response = wrapped_callback(request, *callback_args, **callback_kwargs)
  File "D:\zhujianwei\sem_analysis\sem_index\views.py", line 118, in weibo
    weibo_obj = weibo_instance.get_sort_news_objects(data_source_id_list)["today_sort_news_objects"].limit(10)
  File "D:\zhujianwei\sem_analysis\common\source_media.py", line 154, in get_sort_news_objects
    end_time="2017-01-03 19:20:00")["sort_news_objects"]}
  File "D:\zhujianwei\sem_analysis\common\source_media.py", line 390, in _get_news
    print '========锛?, contents["news_objects"].limit(1)
  File "D:\python27\lib\site-packages\pymongo\cursor.py", line 401, in limit
    self.__check_okay_to_chain()
  File "D:\python27\lib\site-packages\pymongo\cursor.py", line 345, in __check_okay_to_chain
    raise InvalidOperation("cannot set options after executing query")
InvalidOperation: cannot set options after executing query
2017-09-06 10:21:22,194 [Thread-2:8488] [django.request:256] [ERROR]- Internal Server Error: /sem_index/weibo_2/
Traceback (most recent call last):
  File "D:\python27\lib\site-packages\django\core\handlers\base.py", line 132, in get_response
    response = wrapped_callback(request, *callback_args, **callback_kwargs)
  File "D:\zhujianwei\sem_analysis\sem_index\views.py", line 118, in weibo
    weibo_obj = weibo_instance.get_sort_news_objects(data_source_id_list)["today_sort_news_objects"].limit(10)
  File "D:\zhujianwei\sem_analysis\common\source_media.py", line 154, in get_sort_news_objects
    end_time="2017-01-03 19:20:00")["sort_news_objects"]}
  File "D:\zhujianwei\sem_analysis\common\source_media.py", line 390, in _get_news
    print '========:', contents["news_objects"].limit(1)
  File "D:\python27\lib\site-packages\pymongo\cursor.py", line 401, in limit
    self.__check_okay_to_chain()
  File "D:\python27\lib\site-packages\pymongo\cursor.py", line 345, in __check_okay_to_chain
    raise InvalidOperation("cannot set options after executing query")
InvalidOperation: cannot set options after executing query
2017-09-06 10:21:50,525 [Thread-2:952] [django.request:256] [ERROR]- Internal Server Error: /sem_index/weibo_2/
Traceback (most recent call last):
  File "D:\python27\lib\site-packages\django\core\handlers\base.py", line 132, in get_response
    response = wrapped_callback(request, *callback_args, **callback_kwargs)
  File "D:\zhujianwei\sem_analysis\sem_index\views.py", line 118, in weibo
    weibo_obj = weibo_instance.get_sort_news_objects(data_source_id_list)["today_sort_news_objects"].limit(10)
  File "D:\python27\lib\site-packages\pymongo\cursor.py", line 401, in limit
    self.__check_okay_to_chain()
  File "D:\python27\lib\site-packages\pymongo\cursor.py", line 345, in __check_okay_to_chain
    raise InvalidOperation("cannot set options after executing query")
InvalidOperation: cannot set options after executing query
2017-09-06 10:24:02,654 [Thread-2:16152] [django.request:256] [ERROR]- Internal Server Error: /sem_index/weibo_2/
Traceback (most recent call last):
  File "D:\python27\lib\site-packages\django\core\handlers\base.py", line 132, in get_response
    response = wrapped_callback(request, *callback_args, **callback_kwargs)
  File "D:\zhujianwei\sem_analysis\sem_index\views.py", line 118, in weibo
    weibo_obj = weibo_instance.get_sort_news_objects(data_source_id_list)["today_sort_news_objects"].limit(10)
  File "D:\python27\lib\site-packages\pymongo\cursor.py", line 401, in limit
    self.__check_okay_to_chain()
  File "D:\python27\lib\site-packages\pymongo\cursor.py", line 345, in __check_okay_to_chain
    raise InvalidOperation("cannot set options after executing query")
InvalidOperation: cannot set options after executing query
2017-09-06 10:25:05,457 [Thread-2:1072] [django.request:256] [ERROR]- Internal Server Error: /sem_index/weibo_2/
Traceback (most recent call last):
  File "D:\python27\lib\site-packages\django\core\handlers\base.py", line 132, in get_response
    response = wrapped_callback(request, *callback_args, **callback_kwargs)
  File "D:\zhujianwei\sem_analysis\sem_index\views.py", line 118, in weibo
    weibo_obj = weibo_instance.get_sort_news_objects(data_source_id_list)["today_sort_news_objects"].limit(10)
  File "D:\python27\lib\site-packages\pymongo\cursor.py", line 401, in limit
    self.__check_okay_to_chain()
  File "D:\python27\lib\site-packages\pymongo\cursor.py", line 345, in __check_okay_to_chain
    raise InvalidOperation("cannot set options after executing query")
InvalidOperation: cannot set options after executing query
2017-09-06 10:25:50,713 [Thread-2:17496] [django.request:256] [ERROR]- Internal Server Error: /sem_index/weibo_2/
Traceback (most recent call last):
  File "D:\python27\lib\site-packages\django\core\handlers\base.py", line 132, in get_response
    response = wrapped_callback(request, *callback_args, **callback_kwargs)
  File "D:\zhujianwei\sem_analysis\sem_index\views.py", line 118, in weibo
    weibo_obj = weibo_instance.get_sort_news_objects(data_source_id_list)["today_sort_news_objects"].limit(10)
  File "D:\python27\lib\site-packages\pymongo\cursor.py", line 401, in limit
    self.__check_okay_to_chain()
  File "D:\python27\lib\site-packages\pymongo\cursor.py", line 345, in __check_okay_to_chain
    raise InvalidOperation("cannot set options after executing query")
InvalidOperation: cannot set options after executing query
2017-09-06 10:26:33,931 [Thread-2:4300] [django.request:256] [ERROR]- Internal Server Error: /sem_index/weibo_2/
Traceback (most recent call last):
  File "D:\python27\lib\site-packages\django\core\handlers\base.py", line 132, in get_response
    response = wrapped_callback(request, *callback_args, **callback_kwargs)
  File "D:\zhujianwei\sem_analysis\sem_index\views.py", line 118, in weibo
    weibo_obj = weibo_instance.get_sort_news_objects(data_source_id_list)["today_sort_news_objects"].limit(10)
  File "D:\zhujianwei\sem_analysis\common\source_media.py", line 156, in get_sort_news_objects
    print "::::", contents["today_sort_news_objects"].limit(1)
  File "D:\python27\lib\site-packages\pymongo\cursor.py", line 401, in limit
    self.__check_okay_to_chain()
  File "D:\python27\lib\site-packages\pymongo\cursor.py", line 345, in __check_okay_to_chain
    raise InvalidOperation("cannot set options after executing query")
InvalidOperation: cannot set options after executing query
2017-09-06 10:27:13,684 [Thread-2:8048] [django.request:256] [ERROR]- Internal Server Error: /sem_index/weibo_2/
Traceback (most recent call last):
  File "D:\python27\lib\site-packages\django\core\handlers\base.py", line 132, in get_response
    response = wrapped_callback(request, *callback_args, **callback_kwargs)
  File "D:\zhujianwei\sem_analysis\sem_index\views.py", line 118, in weibo
    weibo_obj = weibo_instance.get_sort_news_objects(data_source_id_list)["today_sort_news_objects"].limit(10)
  File "D:\python27\lib\site-packages\pymongo\cursor.py", line 401, in limit
    self.__check_okay_to_chain()
  File "D:\python27\lib\site-packages\pymongo\cursor.py", line 345, in __check_okay_to_chain
    raise InvalidOperation("cannot set options after executing query")
InvalidOperation: cannot set options after executing query
2017-09-06 10:32:38,013 [Thread-8:18212] [django.request:256] [ERROR]- Internal Server Error: /company_influence/company_official_influence_2/
Traceback (most recent call last):
  File "D:\python27\lib\site-packages\django\core\handlers\base.py", line 132, in get_response
    response = wrapped_callback(request, *callback_args, **callback_kwargs)
  File "D:\zhujianwei\sem_analysis\company_influence\views.py", line 42, in company_official_influence
    return JsonResponse(news_count_dict)
  File "D:\python27\lib\site-packages\django\http\response.py", line 535, in __init__
    data = json.dumps(data, cls=encoder)
  File "D:\python27\lib\json\__init__.py", line 251, in dumps
    sort_keys=sort_keys, **kw).encode(obj)
  File "D:\python27\lib\json\encoder.py", line 207, in encode
    chunks = self.iterencode(o, _one_shot=True)
  File "D:\python27\lib\json\encoder.py", line 270, in iterencode
    return _iterencode(o, 0)
  File "D:\python27\lib\site-packages\django\core\serializers\json.py", line 115, in default
    return super(DjangoJSONEncoder, self).default(o)
  File "D:\python27\lib\json\encoder.py", line 184, in default
    raise TypeError(repr(o) + " is not JSON serializable")
TypeError: <pymongo.cursor.Cursor object at 0x00000000052CB358> is not JSON serializable
2017-09-06 10:36:29,411 [Thread-10:8808] [django.request:256] [ERROR]- Internal Server Error: /sem_index/today_hot_2/
Traceback (most recent call last):
  File "D:\python27\lib\site-packages\django\core\handlers\base.py", line 132, in get_response
    response = wrapped_callback(request, *callback_args, **callback_kwargs)
  File "D:\zhujianwei\sem_analysis\sem_index\views.py", line 83, in today_hot
    today_hot_dict[key] = value.get_sort_news_objects(data_source_id_list)["today_sort_news_objects"][0]
  File "D:\python27\lib\site-packages\pymongo\cursor.py", line 534, in __getitem__
    self.__check_okay_to_chain()
  File "D:\python27\lib\site-packages\pymongo\cursor.py", line 345, in __check_okay_to_chain
    raise InvalidOperation("cannot set options after executing query")
InvalidOperation: cannot set options after executing query
2017-09-06 10:39:27,263 [Thread-2:9800] [django.request:256] [ERROR]- Internal Server Error: /sem_index/today_hot_2/
Traceback (most recent call last):
  File "D:\python27\lib\site-packages\django\core\handlers\base.py", line 132, in get_response
    response = wrapped_callback(request, *callback_args, **callback_kwargs)
  File "D:\zhujianwei\sem_analysis\sem_index\views.py", line 83, in today_hot
    today_hot_dict[key] = value.get_sort_news_objects(data_source_id_list)["today_sort_news_objects"][0]
  File "D:\python27\lib\site-packages\pymongo\cursor.py", line 534, in __getitem__
    self.__check_okay_to_chain()
  File "D:\python27\lib\site-packages\pymongo\cursor.py", line 345, in __check_okay_to_chain
    raise InvalidOperation("cannot set options after executing query")
InvalidOperation: cannot set options after executing query
2017-09-06 10:40:33,654 [Thread-5:10392] [django.request:256] [ERROR]- Internal Server Error: /sem_index/today_information_2/
Traceback (most recent call last):
  File "D:\python27\lib\site-packages\django\core\handlers\base.py", line 132, in get_response
    response = wrapped_callback(request, *callback_args, **callback_kwargs)
  File "D:\zhujianwei\sem_analysis\sem_index\views.py", line 103, in today_information
    data_source_id_list)["today_sort_news_objects"].limit(10))
  File "D:\python27\lib\site-packages\pymongo\cursor.py", line 401, in limit
    self.__check_okay_to_chain()
  File "D:\python27\lib\site-packages\pymongo\cursor.py", line 345, in __check_okay_to_chain
    raise InvalidOperation("cannot set options after executing query")
InvalidOperation: cannot set options after executing query
2017-09-06 10:44:11,079 [Thread-6:12252] [django.request:256] [ERROR]- Internal Server Error: /sem_index/app_info_2/
Traceback (most recent call last):
  File "D:\python27\lib\site-packages\django\core\handlers\base.py", line 132, in get_response
    response = wrapped_callback(request, *callback_args, **callback_kwargs)
  File "D:\zhujianwei\sem_analysis\sem_index\views.py", line 158, in app_info
    return JsonResponse(contents)
  File "D:\python27\lib\site-packages\django\http\response.py", line 535, in __init__
    data = json.dumps(data, cls=encoder)
  File "D:\python27\lib\json\__init__.py", line 251, in dumps
    sort_keys=sort_keys, **kw).encode(obj)
  File "D:\python27\lib\json\encoder.py", line 207, in encode
    chunks = self.iterencode(o, _one_shot=True)
  File "D:\python27\lib\json\encoder.py", line 270, in iterencode
    return _iterencode(o, 0)
  File "D:\python27\lib\site-packages\django\core\serializers\json.py", line 115, in default
    return super(DjangoJSONEncoder, self).default(o)
  File "D:\python27\lib\json\encoder.py", line 184, in default
    raise TypeError(repr(o) + " is not JSON serializable")
TypeError: <pymongo.cursor.Cursor object at 0x0000000004480978> is not JSON serializable
2017-09-06 10:47:04,388 [Thread-2:10640] [django.request:256] [ERROR]- Internal Server Error: /sem_index/app_info_2/
Traceback (most recent call last):
  File "D:\python27\lib\site-packages\django\core\handlers\base.py", line 132, in get_response
    response = wrapped_callback(request, *callback_args, **callback_kwargs)
  File "D:\zhujianwei\sem_analysis\sem_index\views.py", line 158, in app_info
    return JsonResponse(contents)
  File "D:\python27\lib\site-packages\django\http\response.py", line 535, in __init__
    data = json.dumps(data, cls=encoder)
  File "D:\python27\lib\json\__init__.py", line 251, in dumps
    sort_keys=sort_keys, **kw).encode(obj)
  File "D:\python27\lib\json\encoder.py", line 207, in encode
    chunks = self.iterencode(o, _one_shot=True)
  File "D:\python27\lib\json\encoder.py", line 270, in iterencode
    return _iterencode(o, 0)
  File "D:\python27\lib\site-packages\django\core\serializers\json.py", line 115, in default
    return super(DjangoJSONEncoder, self).default(o)
  File "D:\python27\lib\json\encoder.py", line 184, in default
    raise TypeError(repr(o) + " is not JSON serializable")
TypeError: <pymongo.cursor.Cursor object at 0x00000000046258D0> is not JSON serializable
2017-09-06 11:06:05,648 [Thread-2:6512] [django.request:256] [ERROR]- Internal Server Error: /sem_index/weibo_2/
Traceback (most recent call last):
  File "D:\python27\lib\site-packages\django\core\handlers\base.py", line 132, in get_response
    response = wrapped_callback(request, *callback_args, **callback_kwargs)
  File "D:\zhujianwei\sem_analysis\sem_index\views.py", line 118, in weibo
    weibo_obj = weibo_instance.get_sort_news_objects(data_source_id_list)["today_sort_news_objects"][:10]
  File "D:\python27\lib\site-packages\pymongo\cursor.py", line 534, in __getitem__
    self.__check_okay_to_chain()
  File "D:\python27\lib\site-packages\pymongo\cursor.py", line 345, in __check_okay_to_chain
    raise InvalidOperation("cannot set options after executing query")
InvalidOperation: cannot set options after executing query
2017-09-06 11:06:27,437 [Thread-2:17624] [django.request:256] [ERROR]- Internal Server Error: /sem_index/weibo_2/
Traceback (most recent call last):
  File "D:\python27\lib\site-packages\django\core\handlers\base.py", line 132, in get_response
    response = wrapped_callback(request, *callback_args, **callback_kwargs)
  File "D:\zhujianwei\sem_analysis\sem_index\views.py", line 118, in weibo
    weibo_obj = weibo_instance.get_sort_news_objects(data_source_id_list)["today_sort_news_objects"][:10]
  File "D:\zhujianwei\sem_analysis\common\source_media.py", line 156, in get_sort_news_objects
    print "content[]", contents["today_sort_news_objects"].limit(1)
  File "D:\python27\lib\site-packages\pymongo\cursor.py", line 401, in limit
    self.__check_okay_to_chain()
  File "D:\python27\lib\site-packages\pymongo\cursor.py", line 345, in __check_okay_to_chain
    raise InvalidOperation("cannot set options after executing query")
InvalidOperation: cannot set options after executing query
2017-09-06 11:11:02,536 [Thread-2:7352] [django.request:256] [ERROR]- Internal Server Error: /company_influence/company_hot_media_2/
Traceback (most recent call last):
  File "D:\python27\lib\site-packages\django\core\handlers\base.py", line 132, in get_response
    response = wrapped_callback(request, *callback_args, **callback_kwargs)
  File "D:\zhujianwei\sem_analysis\company_influence\views.py", line 99, in company_hot_media
    hot_media_sort_list = mongo_data.get_hot_media_sort_list(data_source_id_list)[:10]
  File "D:\zhujianwei\sem_analysis\common\mongo_data.py", line 141, in get_hot_media_sort_list
    hot_media_objects = source_media_instance_dict[key].get_hot_media_objects(data_source_id_list).limit(1)
  File "D:\python27\lib\site-packages\pymongo\cursor.py", line 401, in limit
    self.__check_okay_to_chain()
  File "D:\python27\lib\site-packages\pymongo\cursor.py", line 345, in __check_okay_to_chain
    raise InvalidOperation("cannot set options after executing query")
InvalidOperation: cannot set options after executing query
2017-09-06 11:15:51,634 [Thread-2:9552] [django.request:256] [ERROR]- Internal Server Error: /company_influence/company_hot_media_2/
Traceback (most recent call last):
  File "D:\python27\lib\site-packages\django\core\handlers\base.py", line 132, in get_response
    response = wrapped_callback(request, *callback_args, **callback_kwargs)
  File "D:\zhujianwei\sem_analysis\company_influence\views.py", line 99, in company_hot_media
    hot_media_sort_list = mongo_data.get_hot_media_sort_list(data_source_id_list)[:10]
  File "D:\zhujianwei\sem_analysis\common\mongo_data.py", line 142, in get_hot_media_sort_list
    print hot_media_objects.limit(1)
  File "D:\python27\lib\site-packages\pymongo\cursor.py", line 401, in limit
    self.__check_okay_to_chain()
  File "D:\python27\lib\site-packages\pymongo\cursor.py", line 345, in __check_okay_to_chain
    raise InvalidOperation("cannot set options after executing query")
InvalidOperation: cannot set options after executing query
2017-09-06 13:44:19,880 [Thread-2:18292] [django.request:256] [ERROR]- Internal Server Error: /company_influence/company_hot_media_2/
Traceback (most recent call last):
  File "D:\python27\lib\site-packages\django\core\handlers\base.py", line 132, in get_response
    response = wrapped_callback(request, *callback_args, **callback_kwargs)
  File "D:\zhujianwei\sem_analysis\company_influence\views.py", line 99, in company_hot_media
    hot_media_sort_list = mongo_data.get_hot_media_sort_list(data_source_id_list)[:10]
  File "D:\zhujianwei\sem_analysis\common\mongo_data.py", line 142, in get_hot_media_sort_list
    print hot_media_objects.limit(1)
  File "D:\python27\lib\site-packages\pymongo\cursor.py", line 401, in limit
    self.__check_okay_to_chain()
  File "D:\python27\lib\site-packages\pymongo\cursor.py", line 345, in __check_okay_to_chain
    raise InvalidOperation("cannot set options after executing query")
InvalidOperation: cannot set options after executing query
2017-09-06 13:49:44,197 [Thread-3:3240] [django.request:256] [ERROR]- Internal Server Error: /sem_index/weibo_2/
Traceback (most recent call last):
  File "D:\python27\lib\site-packages\django\core\handlers\base.py", line 132, in get_response
    response = wrapped_callback(request, *callback_args, **callback_kwargs)
  File "D:\zhujianwei\sem_analysis\sem_index\views.py", line 118, in weibo
    weibo_obj = weibo_instance.get_sort_news_objects(data_source_id_list)["today_sort_news_objects"].clone().limit(10)
AttributeError: 'list' object has no attribute 'clone'
2017-09-06 13:52:30,536 [Thread-2:15252] [django.request:256] [ERROR]- Internal Server Error: /sem_index/today_information_2/
Traceback (most recent call last):
  File "D:\python27\lib\site-packages\django\core\handlers\base.py", line 132, in get_response
    response = wrapped_callback(request, *callback_args, **callback_kwargs)
  File "D:\zhujianwei\sem_analysis\sem_index\views.py", line 103, in today_information
    data_source_id_list)["today_sort_news_objects"][:10])
  File "D:\python27\lib\site-packages\pymongo\cursor.py", line 534, in __getitem__
    self.__check_okay_to_chain()
  File "D:\python27\lib\site-packages\pymongo\cursor.py", line 345, in __check_okay_to_chain
    raise InvalidOperation("cannot set options after executing query")
InvalidOperation: cannot set options after executing query
2017-09-06 14:37:35,194 [Thread-4:14284] [django.request:170] [WARNING]- Not Found: /company_influence/get_hot_media_sort_list_2/
2017-09-06 16:07:27,848 [Thread-7:7240] [django.request:170] [WARNING]- Not Found: /favicon.ico
2017-09-06 16:07:27,910 [Thread-8:13360] [django.request:170] [WARNING]- Not Found: /favicon.ico
2017-09-07 09:42:00,023 [Thread-2:15932] [django.request:256] [ERROR]- Internal Server Error: /sem_index/weibo_2/
Traceback (most recent call last):
  File "D:\python27\lib\site-packages\django\core\handlers\base.py", line 132, in get_response
    response = wrapped_callback(request, *callback_args, **callback_kwargs)
  File "D:\zhujianwei\sem_analysis\sem_index\views.py", line 118, in weibo
    weibo_obj = weibo_instance.get_sort_news_objects(data_source_id_list)["today_sort_news_objects"].clone().limit(10)
  File "D:\zhujianwei\sem_analysis\common\source_media.py", line 155, in get_sort_news_objects
    end_time="2017-01-03 19:20:00")["sort_news_objects"]}
  File "D:\zhujianwei\sem_analysis\common\source_media.py", line 376, in _get_news
    news_count = news_objects.count()
  File "D:\python27\lib\site-packages\pymongo\cursor.py", line 711, in count
    return self.__collection._count(cmd, self.__collation)
  File "D:\python27\lib\site-packages\pymongo\collection.py", line 1310, in _count
    collation=collation)
  File "D:\python27\lib\site-packages\pymongo\collection.py", line 232, in _command
    collation=collation)
  File "D:\python27\lib\site-packages\pymongo\pool.py", line 419, in command
    collation=collation)
  File "D:\python27\lib\site-packages\pymongo\network.py", line 116, in command
    parse_write_concern_error=parse_write_concern_error)
  File "D:\python27\lib\site-packages\pymongo\helpers.py", line 210, in _check_command_response
    raise OperationFailure(msg % errmsg, code, response)
OperationFailure: failed on : shard1RS
2017-09-07 09:42:00,571 [Thread-3:15504] [django.request:170] [WARNING]- Not Found: /favicon.ico
2017-09-07 09:54:53,430 [Thread-5:4700] [django.request:170] [WARNING]- Not Found: /sem_index/weibo_(2,)/
2017-09-07 09:55:46,348 [Thread-2:17304] [django.request:170] [WARNING]- Not Found: /sem_index/weibo_(2,)/
2017-09-07 09:55:47,878 [Thread-3:11536] [django.request:170] [WARNING]- Not Found: /sem_index/weibo_(2,)/
2017-09-07 09:55:48,446 [Thread-4:5736] [django.request:170] [WARNING]- Not Found: /sem_index/weibo_(2,)/
2017-09-07 09:55:48,651 [Thread-5:15068] [django.request:170] [WARNING]- Not Found: /sem_index/weibo_(2,)/
2017-09-07 09:56:11,184 [Thread-6:15836] [django.request:170] [WARNING]- Not Found: /sem_index/weibo_(2,)/
2017-09-07 09:56:11,956 [Thread-7:11832] [django.request:170] [WARNING]- Not Found: /sem_index/weibo_(2,)/
2017-09-07 09:56:12,539 [Thread-8:11516] [django.request:170] [WARNING]- Not Found: /sem_index/weibo_(2,)/
2017-09-07 09:56:13,596 [Thread-9:10556] [django.request:170] [WARNING]- Not Found: /sem_index/weibo_(2,)/
2017-09-07 09:56:13,829 [Thread-10:6540] [django.request:170] [WARNING]- Not Found: /sem_index/weibo_(2,)/
2017-09-07 09:56:14,030 [Thread-11:15132] [django.request:170] [WARNING]- Not Found: /sem_index/weibo_(2,)/
2017-09-07 09:56:14,204 [Thread-12:13820] [django.request:170] [WARNING]- Not Found: /sem_index/weibo_(2,)/
2017-09-07 09:56:14,380 [Thread-13:2276] [django.request:170] [WARNING]- Not Found: /sem_index/weibo_(2,)/
2017-09-07 09:56:19,790 [Thread-14:15908] [django.request:256] [ERROR]- Internal Server Error: /sem_index/weibo_(2)/
Traceback (most recent call last):
  File "D:\python27\lib\site-packages\django\core\handlers\base.py", line 132, in get_response
    response = wrapped_callback(request, *callback_args, **callback_kwargs)
  File "D:\zhujianwei\sem_analysis\sem_index\views.py", line 116, in weibo
    data_source_id_list = mysql_data.get_data_source_id_list(int(company_id))
ValueError: invalid literal for int() with base 10: '(2)'
2017-09-07 09:56:49,526 [Thread-2:13256] [django.request:256] [ERROR]- Internal Server Error: /sem_index/weibo_[2]/
Traceback (most recent call last):
  File "D:\python27\lib\site-packages\django\core\handlers\base.py", line 132, in get_response
    response = wrapped_callback(request, *callback_args, **callback_kwargs)
  File "D:\zhujianwei\sem_analysis\sem_index\views.py", line 116, in weibo
    data_source_id_list = mysql_data.get_data_source_id_list(int(company_id))
ValueError: invalid literal for int() with base 10: '[2]'
2017-09-07 09:57:50,456 [Thread-2:13880] [django.request:256] [ERROR]- Internal Server Error: /sem_index/weibo_[2]/
Traceback (most recent call last):
  File "D:\python27\lib\site-packages\django\core\handlers\base.py", line 132, in get_response
    response = wrapped_callback(request, *callback_args, **callback_kwargs)
  File "D:\zhujianwei\sem_analysis\sem_index\views.py", line 116, in weibo
    data_source_id_list = mysql_data.get_data_source_id_list(int(company_id))
ValueError: invalid literal for int() with base 10: '[2]'
2017-09-07 09:58:13,062 [Thread-2:14292] [django.request:256] [ERROR]- Internal Server Error: /sem_index/weibo_[2]/
Traceback (most recent call last):
  File "D:\python27\lib\site-packages\django\core\handlers\base.py", line 132, in get_response
    response = wrapped_callback(request, *callback_args, **callback_kwargs)
  File "D:\zhujianwei\sem_analysis\sem_index\views.py", line 116, in weibo
    data_source_id_list = mysql_data.get_data_source_id_list(int(company_id))
ValueError: invalid literal for int() with base 10: '[2]'
2017-09-07 09:58:34,341 [Thread-5:7928] [django.request:256] [ERROR]- Internal Server Error: /sem_index/weibo_[2]/
Traceback (most recent call last):
  File "D:\python27\lib\site-packages\django\core\handlers\base.py", line 132, in get_response
    response = wrapped_callback(request, *callback_args, **callback_kwargs)
  File "D:\zhujianwei\sem_analysis\sem_index\views.py", line 116, in weibo
    data_source_id_list = mysql_data.get_data_source_id_list(company_id)
ValueError: invalid literal for int() with base 10: '[2]'
2017-09-07 09:58:37,931 [Thread-2:6232] [django.request:256] [ERROR]- Internal Server Error: /sem_index/weibo_[2]/
Traceback (most recent call last):
  File "D:\python27\lib\site-packages\django\core\handlers\base.py", line 132, in get_response
    response = wrapped_callback(request, *callback_args, **callback_kwargs)
  File "D:\zhujianwei\sem_analysis\sem_index\views.py", line 118, in weibo
    weibo_obj = weibo_instance.get_sort_news_objects(data_source_id_list)["today_sort_news_objects"].clone().limit(10)
  File "D:\zhujianwei\sem_analysis\common\source_media.py", line 155, in get_sort_news_objects
    end_time="2017-01-03 19:20:00")["sort_news_objects"]}
  File "D:\zhujianwei\sem_analysis\common\source_media.py", line 376, in _get_news
    news_count = news_objects.count()
  File "D:\python27\lib\site-packages\pymongo\cursor.py", line 711, in count
    return self.__collection._count(cmd, self.__collation)
  File "D:\python27\lib\site-packages\pymongo\collection.py", line 1310, in _count
    collation=collation)
  File "D:\python27\lib\site-packages\pymongo\collection.py", line 232, in _command
    collation=collation)
  File "D:\python27\lib\site-packages\pymongo\pool.py", line 419, in command
    collation=collation)
  File "D:\python27\lib\site-packages\pymongo\network.py", line 116, in command
    parse_write_concern_error=parse_write_concern_error)
  File "D:\python27\lib\site-packages\pymongo\helpers.py", line 210, in _check_command_response
    raise OperationFailure(msg % errmsg, code, response)
OperationFailure: failed on : shard1RS
2017-09-07 09:59:28,674 [Thread-2:16572] [django.request:256] [ERROR]- Internal Server Error: /sem_index/weibo_[2]/
Traceback (most recent call last):
  File "D:\python27\lib\site-packages\django\core\handlers\base.py", line 132, in get_response
    response = wrapped_callback(request, *callback_args, **callback_kwargs)
  File "D:\zhujianwei\sem_analysis\sem_index\views.py", line 118, in weibo
    weibo_obj = weibo_instance.get_sort_news_objects(data_source_id_list)["today_sort_news_objects"].clone().limit(10)
  File "D:\zhujianwei\sem_analysis\common\source_media.py", line 155, in get_sort_news_objects
    end_time="2017-01-03 19:20:00")["sort_news_objects"]}
  File "D:\zhujianwei\sem_analysis\common\source_media.py", line 376, in _get_news
    news_count = news_objects.count()
  File "D:\python27\lib\site-packages\pymongo\cursor.py", line 711, in count
    return self.__collection._count(cmd, self.__collation)
  File "D:\python27\lib\site-packages\pymongo\collection.py", line 1310, in _count
    collation=collation)
  File "D:\python27\lib\site-packages\pymongo\collection.py", line 232, in _command
    collation=collation)
  File "D:\python27\lib\site-packages\pymongo\pool.py", line 419, in command
    collation=collation)
  File "D:\python27\lib\site-packages\pymongo\network.py", line 116, in command
    parse_write_concern_error=parse_write_concern_error)
  File "D:\python27\lib\site-packages\pymongo\helpers.py", line 210, in _check_command_response
    raise OperationFailure(msg % errmsg, code, response)
OperationFailure: failed on : shard1RS
2017-09-07 10:00:45,566 [Thread-2:9104] [django.request:256] [ERROR]- Internal Server Error: /sem_index/weibo_[2]/
Traceback (most recent call last):
  File "D:\python27\lib\site-packages\django\core\handlers\base.py", line 132, in get_response
    response = wrapped_callback(request, *callback_args, **callback_kwargs)
  File "D:\zhujianwei\sem_analysis\sem_index\views.py", line 118, in weibo
    weibo_obj = weibo_instance.get_sort_news_objects(data_source_id_list)["today_sort_news_objects"].clone().limit(10)
  File "D:\zhujianwei\sem_analysis\common\source_media.py", line 155, in get_sort_news_objects
    end_time="2017-01-03 19:20:00")["sort_news_objects"]}
  File "D:\zhujianwei\sem_analysis\common\source_media.py", line 376, in _get_news
    news_count = news_objects.count()
  File "D:\python27\lib\site-packages\pymongo\cursor.py", line 711, in count
    return self.__collection._count(cmd, self.__collation)
  File "D:\python27\lib\site-packages\pymongo\collection.py", line 1310, in _count
    collation=collation)
  File "D:\python27\lib\site-packages\pymongo\collection.py", line 232, in _command
    collation=collation)
  File "D:\python27\lib\site-packages\pymongo\pool.py", line 419, in command
    collation=collation)
  File "D:\python27\lib\site-packages\pymongo\network.py", line 116, in command
    parse_write_concern_error=parse_write_concern_error)
  File "D:\python27\lib\site-packages\pymongo\helpers.py", line 210, in _check_command_response
    raise OperationFailure(msg % errmsg, code, response)
OperationFailure: failed on : shard1RS
2017-09-07 10:01:07,260 [Thread-4:7032] [django.request:170] [WARNING]- Not Found: /sem_index/weibo_2/
2017-09-07 10:01:23,809 [Thread-2:2900] [django.request:256] [ERROR]- Internal Server Error: /sem_index/weibo_2/
Traceback (most recent call last):
  File "D:\python27\lib\site-packages\django\core\handlers\base.py", line 132, in get_response
    response = wrapped_callback(request, *callback_args, **callback_kwargs)
  File "D:\zhujianwei\sem_analysis\sem_index\views.py", line 118, in weibo
    weibo_obj = weibo_instance.get_sort_news_objects(data_source_id_list)["today_sort_news_objects"].clone().limit(10)
  File "D:\zhujianwei\sem_analysis\common\source_media.py", line 155, in get_sort_news_objects
    end_time="2017-01-03 19:20:00")["sort_news_objects"]}
  File "D:\zhujianwei\sem_analysis\common\source_media.py", line 376, in _get_news
    news_count = news_objects.count()
  File "D:\python27\lib\site-packages\pymongo\cursor.py", line 711, in count
    return self.__collection._count(cmd, self.__collation)
  File "D:\python27\lib\site-packages\pymongo\collection.py", line 1310, in _count
    collation=collation)
  File "D:\python27\lib\site-packages\pymongo\collection.py", line 232, in _command
    collation=collation)
  File "D:\python27\lib\site-packages\pymongo\pool.py", line 419, in command
    collation=collation)
  File "D:\python27\lib\site-packages\pymongo\network.py", line 116, in command
    parse_write_concern_error=parse_write_concern_error)
  File "D:\python27\lib\site-packages\pymongo\helpers.py", line 210, in _check_command_response
    raise OperationFailure(msg % errmsg, code, response)
OperationFailure: failed on : shard1RS
2017-09-07 10:01:57,872 [Thread-2:10060] [django.request:256] [ERROR]- Internal Server Error: /sem_index/weibo_2/
Traceback (most recent call last):
  File "D:\python27\lib\site-packages\django\core\handlers\base.py", line 132, in get_response
    response = wrapped_callback(request, *callback_args, **callback_kwargs)
  File "D:\zhujianwei\sem_analysis\sem_index\views.py", line 118, in weibo
    weibo_obj = weibo_instance.get_sort_news_objects(data_source_id_list)["today_sort_news_objects"].clone().limit(10)
  File "D:\zhujianwei\sem_analysis\common\source_media.py", line 155, in get_sort_news_objects
    end_time="2017-01-03 19:20:00")["sort_news_objects"]}
  File "D:\zhujianwei\sem_analysis\common\source_media.py", line 376, in _get_news
    news_count = news_objects.count()
  File "D:\python27\lib\site-packages\pymongo\cursor.py", line 711, in count
    return self.__collection._count(cmd, self.__collation)
  File "D:\python27\lib\site-packages\pymongo\collection.py", line 1310, in _count
    collation=collation)
  File "D:\python27\lib\site-packages\pymongo\collection.py", line 232, in _command
    collation=collation)
  File "D:\python27\lib\site-packages\pymongo\pool.py", line 419, in command
    collation=collation)
  File "D:\python27\lib\site-packages\pymongo\network.py", line 116, in command
    parse_write_concern_error=parse_write_concern_error)
  File "D:\python27\lib\site-packages\pymongo\helpers.py", line 210, in _check_command_response
    raise OperationFailure(msg % errmsg, code, response)
OperationFailure: failed on : shard1RS
2017-09-07 10:02:39,469 [Thread-4:17860] [django.request:256] [ERROR]- Internal Server Error: /sem_index/weibo_23/
Traceback (most recent call last):
  File "D:\python27\lib\site-packages\django\core\handlers\base.py", line 132, in get_response
    response = wrapped_callback(request, *callback_args, **callback_kwargs)
  File "D:\zhujianwei\sem_analysis\sem_index\views.py", line 118, in weibo
    weibo_obj = weibo_instance.get_sort_news_objects(data_source_id_list)["today_sort_news_objects"].clone().limit(10)
  File "D:\zhujianwei\sem_analysis\common\source_media.py", line 155, in get_sort_news_objects
    end_time="2017-01-03 19:20:00")["sort_news_objects"]}
  File "D:\zhujianwei\sem_analysis\common\source_media.py", line 376, in _get_news
    news_count = news_objects.count()
  File "D:\python27\lib\site-packages\pymongo\cursor.py", line 711, in count
    return self.__collection._count(cmd, self.__collation)
  File "D:\python27\lib\site-packages\pymongo\collection.py", line 1310, in _count
    collation=collation)
  File "D:\python27\lib\site-packages\pymongo\collection.py", line 232, in _command
    collation=collation)
  File "D:\python27\lib\site-packages\pymongo\pool.py", line 419, in command
    collation=collation)
  File "D:\python27\lib\site-packages\pymongo\network.py", line 116, in command
    parse_write_concern_error=parse_write_concern_error)
  File "D:\python27\lib\site-packages\pymongo\helpers.py", line 210, in _check_command_response
    raise OperationFailure(msg % errmsg, code, response)
OperationFailure: failed on : shard1RS
2017-09-07 10:08:35,693 [Thread-2:17516] [django.request:256] [ERROR]- Internal Server Error: /sem_index/weibo_2/
Traceback (most recent call last):
  File "D:\python27\lib\site-packages\django\core\handlers\base.py", line 132, in get_response
    response = wrapped_callback(request, *callback_args, **callback_kwargs)
  File "D:\zhujianwei\sem_analysis\sem_index\views.py", line 122, in weibo
    return JsonResponse(contents)
  File "D:\python27\lib\site-packages\django\http\response.py", line 535, in __init__
    data = json.dumps(data, cls=encoder)
  File "D:\python27\lib\json\__init__.py", line 251, in dumps
    sort_keys=sort_keys, **kw).encode(obj)
  File "D:\python27\lib\json\encoder.py", line 207, in encode
    chunks = self.iterencode(o, _one_shot=True)
  File "D:\python27\lib\json\encoder.py", line 270, in iterencode
    return _iterencode(o, 0)
  File "D:\python27\lib\site-packages\django\core\serializers\json.py", line 115, in default
    return super(DjangoJSONEncoder, self).default(o)
  File "D:\python27\lib\json\encoder.py", line 184, in default
    raise TypeError(repr(o) + " is not JSON serializable")
TypeError: ObjectId('593e3934fecb1d0be7a96ae8') is not JSON serializable
2017-09-07 10:09:13,157 [Thread-2:16700] [django.request:256] [ERROR]- Internal Server Error: /sem_index/weibo_2/
Traceback (most recent call last):
  File "D:\python27\lib\site-packages\django\core\handlers\base.py", line 132, in get_response
    response = wrapped_callback(request, *callback_args, **callback_kwargs)
  File "D:\zhujianwei\sem_analysis\sem_index\views.py", line 122, in weibo
    return JsonResponse(contents)
  File "D:\python27\lib\site-packages\django\http\response.py", line 535, in __init__
    data = json.dumps(data, cls=encoder)
  File "D:\python27\lib\json\__init__.py", line 251, in dumps
    sort_keys=sort_keys, **kw).encode(obj)
  File "D:\python27\lib\json\encoder.py", line 207, in encode
    chunks = self.iterencode(o, _one_shot=True)
  File "D:\python27\lib\json\encoder.py", line 270, in iterencode
    return _iterencode(o, 0)
  File "D:\python27\lib\site-packages\django\core\serializers\json.py", line 115, in default
    return super(DjangoJSONEncoder, self).default(o)
  File "D:\python27\lib\json\encoder.py", line 184, in default
    raise TypeError(repr(o) + " is not JSON serializable")
TypeError: ObjectId('593e3934fecb1d0be7a96ae8') is not JSON serializable
2017-09-08 09:17:06,667 [Thread-3:14260] [django.request:170] [WARNING]- Not Found: /favicon.ico
2017-09-08 10:41:50,582 [Thread-2:6072] [django.request:256] [ERROR]- Internal Server Error: /app_info/app_comment_2/
Traceback (most recent call last):
  File "D:\python27\lib\site-packages\django\core\handlers\base.py", line 132, in get_response
    response = wrapped_callback(request, *callback_args, **callback_kwargs)
  File "D:\zhujianwei\sem_analysis\app_info\views.py", line 28, in app_comment
    app_comment_info = app_obj.get_app_comments_info(data_source_id_list)
  File "D:\zhujianwei\sem_analysis\common\source_media.py", line 569, in get_app_comments_info
    for obj in sort_comments_objects:
  File "D:\python27\lib\site-packages\pymongo\cursor.py", line 1114, in next
    if len(self.__data) or self._refresh():
  File "D:\python27\lib\site-packages\pymongo\cursor.py", line 1036, in _refresh
    self.__collation))
  File "D:\python27\lib\site-packages\pymongo\cursor.py", line 928, in __send_message
    helpers._check_command_response(doc['data'][0])
  File "D:\python27\lib\site-packages\pymongo\helpers.py", line 210, in _check_command_response
    raise OperationFailure(msg % errmsg, code, response)
OperationFailure: $and/$or/$nor must be a nonempty array
2017-09-08 11:01:12,305 [Thread-2:14340] [django.request:256] [ERROR]- Internal Server Error: /app_info/app_comment_2/
Traceback (most recent call last):
  File "D:\python27\lib\site-packages\django\core\handlers\base.py", line 132, in get_response
    response = wrapped_callback(request, *callback_args, **callback_kwargs)
  File "D:\zhujianwei\sem_analysis\app_info\views.py", line 28, in app_comment
    app_comment_info = app_obj.get_app_comments_info(data_source_id_list)
  File "D:\zhujianwei\sem_analysis\common\source_media.py", line 568, in get_app_comments_info
    print sort_comments_objects.count()
  File "D:\python27\lib\site-packages\pymongo\cursor.py", line 711, in count
    return self.__collection._count(cmd, self.__collation)
  File "D:\python27\lib\site-packages\pymongo\collection.py", line 1310, in _count
    collation=collation)
  File "D:\python27\lib\site-packages\pymongo\collection.py", line 232, in _command
    collation=collation)
  File "D:\python27\lib\site-packages\pymongo\pool.py", line 419, in command
    collation=collation)
  File "D:\python27\lib\site-packages\pymongo\network.py", line 116, in command
    parse_write_concern_error=parse_write_concern_error)
  File "D:\python27\lib\site-packages\pymongo\helpers.py", line 210, in _check_command_response
    raise OperationFailure(msg % errmsg, code, response)
OperationFailure: failed on : shard1RS
2017-09-08 11:01:54,882 [Thread-2:11752] [django.request:256] [ERROR]- Internal Server Error: /app_info/app_comment_2/
Traceback (most recent call last):
  File "D:\python27\lib\site-packages\django\core\handlers\base.py", line 132, in get_response
    response = wrapped_callback(request, *callback_args, **callback_kwargs)
  File "D:\zhujianwei\sem_analysis\app_info\views.py", line 28, in app_comment
    app_comment_info = app_obj.get_app_comments_info(data_source_id_list)
  File "D:\zhujianwei\sem_analysis\common\source_media.py", line 569, in get_app_comments_info
    for obj in sort_comments_objects:
  File "D:\python27\lib\site-packages\pymongo\cursor.py", line 1114, in next
    if len(self.__data) or self._refresh():
  File "D:\python27\lib\site-packages\pymongo\cursor.py", line 1036, in _refresh
    self.__collation))
  File "D:\python27\lib\site-packages\pymongo\cursor.py", line 928, in __send_message
    helpers._check_command_response(doc['data'][0])
  File "D:\python27\lib\site-packages\pymongo\helpers.py", line 210, in _check_command_response
    raise OperationFailure(msg % errmsg, code, response)
OperationFailure: $and/$or/$nor must be a nonempty array
2017-09-08 11:02:24,994 [Thread-2:10976] [django.request:256] [ERROR]- Internal Server Error: /app_info/app_comment_2/
Traceback (most recent call last):
  File "D:\python27\lib\site-packages\django\core\handlers\base.py", line 132, in get_response
    response = wrapped_callback(request, *callback_args, **callback_kwargs)
  File "D:\zhujianwei\sem_analysis\app_info\views.py", line 28, in app_comment
    app_comment_info = app_obj.get_app_comments_info(data_source_id_list)
  File "D:\zhujianwei\sem_analysis\common\source_media.py", line 568, in get_app_comments_info
    print sort_comments_objects[0]
  File "D:\python27\lib\site-packages\pymongo\cursor.py", line 568, in __getitem__
    for doc in clone:
  File "D:\python27\lib\site-packages\pymongo\cursor.py", line 1114, in next
    if len(self.__data) or self._refresh():
  File "D:\python27\lib\site-packages\pymongo\cursor.py", line 1036, in _refresh
    self.__collation))
  File "D:\python27\lib\site-packages\pymongo\cursor.py", line 928, in __send_message
    helpers._check_command_response(doc['data'][0])
  File "D:\python27\lib\site-packages\pymongo\helpers.py", line 210, in _check_command_response
    raise OperationFailure(msg % errmsg, code, response)
OperationFailure: $and/$or/$nor must be a nonempty array
2017-09-08 11:02:48,805 [Thread-2:18076] [django.request:256] [ERROR]- Internal Server Error: /app_info/app_comment_2/
Traceback (most recent call last):
  File "D:\python27\lib\site-packages\django\core\handlers\base.py", line 132, in get_response
    response = wrapped_callback(request, *callback_args, **callback_kwargs)
  File "D:\zhujianwei\sem_analysis\app_info\views.py", line 28, in app_comment
    app_comment_info = app_obj.get_app_comments_info(data_source_id_list)
  File "D:\zhujianwei\sem_analysis\common\source_media.py", line 568, in get_app_comments_info
    print sort_comments_objects.count()
  File "D:\python27\lib\site-packages\pymongo\cursor.py", line 711, in count
    return self.__collection._count(cmd, self.__collation)
  File "D:\python27\lib\site-packages\pymongo\collection.py", line 1310, in _count
    collation=collation)
  File "D:\python27\lib\site-packages\pymongo\collection.py", line 232, in _command
    collation=collation)
  File "D:\python27\lib\site-packages\pymongo\pool.py", line 419, in command
    collation=collation)
  File "D:\python27\lib\site-packages\pymongo\network.py", line 116, in command
    parse_write_concern_error=parse_write_concern_error)
  File "D:\python27\lib\site-packages\pymongo\helpers.py", line 210, in _check_command_response
    raise OperationFailure(msg % errmsg, code, response)
OperationFailure: failed on : shard1RS
2017-09-08 11:04:46,262 [Thread-2:2384] [django.request:256] [ERROR]- Internal Server Error: /app_info/app_comment_2/
Traceback (most recent call last):
  File "D:\python27\lib\site-packages\django\core\handlers\base.py", line 132, in get_response
    response = wrapped_callback(request, *callback_args, **callback_kwargs)
  File "D:\zhujianwei\sem_analysis\app_info\views.py", line 28, in app_comment
    app_comment_info = app_obj.get_app_comments_info(data_source_id_list)
  File "D:\zhujianwei\sem_analysis\common\source_media.py", line 569, in get_app_comments_info
    for obj in sort_comments_objects:
  File "D:\python27\lib\site-packages\pymongo\cursor.py", line 1114, in next
    if len(self.__data) or self._refresh():
  File "D:\python27\lib\site-packages\pymongo\cursor.py", line 1036, in _refresh
    self.__collation))
  File "D:\python27\lib\site-packages\pymongo\cursor.py", line 928, in __send_message
    helpers._check_command_response(doc['data'][0])
  File "D:\python27\lib\site-packages\pymongo\helpers.py", line 210, in _check_command_response
    raise OperationFailure(msg % errmsg, code, response)
OperationFailure: $and/$or/$nor must be a nonempty array
2017-09-08 11:07:17,437 [Thread-2:7500] [django.request:256] [ERROR]- Internal Server Error: /app_info/app_comment_2/
Traceback (most recent call last):
  File "D:\python27\lib\site-packages\django\core\handlers\base.py", line 132, in get_response
    response = wrapped_callback(request, *callback_args, **callback_kwargs)
  File "D:\zhujianwei\sem_analysis\app_info\views.py", line 28, in app_comment
    app_comment_info = app_obj.get_app_comments_info(data_source_id_list)
  File "D:\zhujianwei\sem_analysis\common\source_media.py", line 572, in get_app_comments_info
    if obj["sentiment"] == "negative":
KeyError: 'sentiment'
2017-09-19 16:30:03,650 [Thread-3:20296] [django.request:170] [WARNING]- Not Found: /favicon.ico
2017-09-19 16:39:55,914 [Thread-3:14304] [django.request:170] [WARNING]- Not Found: /app_info/app_bangdan_2
2017-09-19 16:40:08,944 [Thread-5:18416] [django.request:256] [ERROR]- Internal Server Error: /app_info/app_bangdan_info_2/
Traceback (most recent call last):
  File "D:\python27\lib\site-packages\django\core\handlers\base.py", line 132, in get_response
    response = wrapped_callback(request, *callback_args, **callback_kwargs)
  File "D:\zhujianwei\sem_analysis\app_info\views.py", line 21, in app_bangdan_info
    app_bangdan_info_obj = app_obj.get_app_bangdan_info_obj(data_source_id_list)
  File "D:\zhujianwei\sem_analysis\common\source_media.py", line 604, in get_app_bangdan_info_obj
    return serialize_news_obj(app_bangdan_info_obj)
  File "D:\zhujianwei\sem_analysis\common\common.py", line 56, in serialize_news_obj
    for item in news_obj:
  File "D:\python27\lib\site-packages\pymongo\cursor.py", line 1114, in next
    if len(self.__data) or self._refresh():
  File "D:\python27\lib\site-packages\pymongo\cursor.py", line 1036, in _refresh
    self.__collation))
  File "D:\python27\lib\site-packages\pymongo\cursor.py", line 928, in __send_message
    helpers._check_command_response(doc['data'][0])
  File "D:\python27\lib\site-packages\pymongo\helpers.py", line 210, in _check_command_response
    raise OperationFailure(msg % errmsg, code, response)
OperationFailure: $and/$or/$nor must be a nonempty array
2017-09-20 10:32:25,049 [Thread-3:11064] [django.request:170] [WARNING]- Not Found: /favicon.ico
2017-09-25 15:37:28,632 [Thread-3:8216] [django.request:170] [WARNING]- Not Found: /favicon.ico
2017-09-27 10:05:25,371 [Thread-3:13000] [django.request:170] [WARNING]- Not Found: /favicon.ico
2017-09-27 10:13:30,121 [Thread-8:1516] [django.request:256] [ERROR]- Internal Server Error: /sem_index/influence_show_2/
Traceback (most recent call last):
  File "D:\python27\lib\site-packages\django\core\handlers\base.py", line 132, in get_response
    response = wrapped_callback(request, *callback_args, **callback_kwargs)
  File "D:\zhujianwei\sem_analysis\sem_index\views.py", line 24, in influence_show
    total_influence_dict = mongo_data.get_total_influence(data_source_id_list, paras=settings.MONGO_PARA)
  File "D:\zhujianwei\sem_analysis\common\mongo_data.py", line 52, in get_total_influence
    total_use_defined_influence += influence_dict["use_defined_influence"]
KeyError: 'use_defined_influence'
2017-09-27 10:15:55,711 [Thread-9:19156] [django.request:256] [ERROR]- Internal Server Error: /sem_index/influence_show_2/
Traceback (most recent call last):
  File "D:\python27\lib\site-packages\django\core\handlers\base.py", line 132, in get_response
    response = wrapped_callback(request, *callback_args, **callback_kwargs)
  File "D:\zhujianwei\sem_analysis\sem_index\views.py", line 24, in influence_show
    total_influence_dict = mongo_data.get_total_influence(data_source_id_list, paras=settings.MONGO_PARA)
  File "D:\zhujianwei\sem_analysis\common\mongo_data.py", line 52, in get_total_influence
    total_use_defined_influence += influence_dict["use_defined_influence"]
KeyError: 'use_defined_influence'
2017-09-27 10:18:12,446 [Thread-2:6884] [django.request:256] [ERROR]- Internal Server Error: /sem_index/influence_show_2/
Traceback (most recent call last):
  File "D:\python27\lib\site-packages\django\core\handlers\base.py", line 132, in get_response
    response = wrapped_callback(request, *callback_args, **callback_kwargs)
  File "D:\zhujianwei\sem_analysis\sem_index\views.py", line 24, in influence_show
    total_influence_dict = mongo_data.get_total_influence(data_source_id_list, paras=settings.MONGO_PARA)
  File "D:\zhujianwei\sem_analysis\common\mongo_data.py", line 52, in get_total_influence
    total_use_defined_influence += influence_dict.get("use_defined_influence")
TypeError: unsupported operand type(s) for +=: 'int' and 'NoneType'
2017-09-27 10:26:24,082 [Thread-2:2500] [django.request:256] [ERROR]- Internal Server Error: /sem_index/influence_show_2/
Traceback (most recent call last):
  File "D:\python27\lib\site-packages\django\core\handlers\base.py", line 132, in get_response
    response = wrapped_callback(request, *callback_args, **callback_kwargs)
  File "D:\zhujianwei\sem_analysis\sem_index\views.py", line 26, in influence_show
    paras=settings.MONGO_PARA)
  File "D:\zhujianwei\sem_analysis\common\mongo_data.py", line 128, in get_total_influence_change
    ) / float(total_influence_dict["total_last_seven_influence"])
ZeroDivisionError: float division by zero
2017-09-27 10:31:53,056 [Thread-6:19516] [django.request:256] [ERROR]- Internal Server Error: /company_influence/company_official_influence_2/
Traceback (most recent call last):
  File "D:\python27\lib\site-packages\django\core\handlers\base.py", line 132, in get_response
    response = wrapped_callback(request, *callback_args, **callback_kwargs)
  File "D:\zhujianwei\sem_analysis\company_influence\views.py", line 41, in company_official_influence
    end_time=end_time)
  File "D:\zhujianwei\sem_analysis\common\source_media.py", line 195, in get_news_count
    news_count = self._get_news(data_source_id_list, start_time=start_time, end_time=end_time)["news_count"].clone()
AttributeError: 'int' object has no attribute 'clone'
2017-09-27 10:56:59,450 [Thread-2:10840] [django.request:256] [ERROR]- Internal Server Error: /company_influence/company_official_influence_2/
Traceback (most recent call last):
  File "D:\python27\lib\site-packages\django\core\handlers\base.py", line 132, in get_response
    response = wrapped_callback(request, *callback_args, **callback_kwargs)
  File "D:\zhujianwei\sem_analysis\company_influence\views.py", line 46, in company_official_influence
    end_time=end_time)
  File "D:\zhujianwei\sem_analysis\common\source_media.py", line 175, in get_avg_click_repost_read
    avg_click_count = float("%.2f" % (float(click_count) / weixin_article_count))
ZeroDivisionError: float division by zero
2017-09-27 11:00:49,687 [Thread-2:21052] [django.request:256] [ERROR]- Internal Server Error: /company_influence/company_information_influence_2/
Traceback (most recent call last):
  File "D:\python27\lib\site-packages\django\core\handlers\base.py", line 132, in get_response
    response = wrapped_callback(request, *callback_args, **callback_kwargs)
  File "D:\zhujianwei\sem_analysis\company_influence\views.py", line 68, in company_information_influence
    end_time=end_time)
  File "D:\zhujianwei\sem_analysis\common\mongo_data.py", line 72, in get_total_influence
    sentiment_influence_dict["today_sentiment_influence_dict"]["negative"]
KeyError: 'negative'
2017-09-27 11:07:18,838 [Thread-2:13096] [django.request:256] [ERROR]- Internal Server Error: /company_influence/company_information_influence_2/
Traceback (most recent call last):
  File "D:\python27\lib\site-packages\django\core\handlers\base.py", line 132, in get_response
    response = wrapped_callback(request, *callback_args, **callback_kwargs)
  File "D:\zhujianwei\sem_analysis\company_influence\views.py", line 68, in company_information_influence
    end_time=end_time)
  File "D:\zhujianwei\sem_analysis\common\mongo_data.py", line 73, in get_total_influence
    sentiment_influence_dict["today_sentiment_influence_dict"]["negative"]
KeyError: 'negative'
2017-09-27 11:11:56,960 [Thread-6:11528] [django.request:256] [ERROR]- Internal Server Error: /company_influence/company_hot_media_2/
Traceback (most recent call last):
  File "D:\python27\lib\site-packages\django\core\handlers\base.py", line 132, in get_response
    response = wrapped_callback(request, *callback_args, **callback_kwargs)
  File "D:\zhujianwei\sem_analysis\company_influence\views.py", line 117, in company_hot_media
    paras=settings.MONGO_PARA)[:10]
  File "D:\zhujianwei\sem_analysis\common\mongo_data.py", line 186, in get_hot_media_sort_list
    hot_media_objects = source_media_instance_dict[key].get_hot_media_objects(data_source_id_list).clone()
AttributeError: 'NoneType' object has no attribute 'clone'
2017-09-27 11:14:47,838 [Thread-4:13480] [django.request:256] [ERROR]- Internal Server Error: /product_influence/product_data_statistics_2/
Traceback (most recent call last):
  File "D:\python27\lib\site-packages\django\core\handlers\base.py", line 132, in get_response
    response = wrapped_callback(request, *callback_args, **callback_kwargs)
  File "D:\zhujianwei\sem_analysis\product_influence\views.py", line 58, in product_data_statistics
    start_time = request.POST("start_time", common.default_start_time)
TypeError: 'QueryDict' object is not callable
2017-09-27 11:17:42,164 [Thread-8:11360] [django.request:170] [WARNING]- Not Found: /product_influence/event_propagation_trace_2/
2017-09-27 11:17:50,446 [Thread-9:19228] [django.request:170] [WARNING]- Not Found: /evnet_influence/event_propagation_trace_2/
2017-09-27 11:18:24,760 [Thread-13:9540] [django.request:256] [ERROR]- Internal Server Error: /event_influence/event_attitude_statistics_2/
Traceback (most recent call last):
  File "D:\python27\lib\site-packages\django\core\handlers\base.py", line 132, in get_response
    response = wrapped_callback(request, *callback_args, **callback_kwargs)
  File "D:\zhujianwei\sem_analysis\event_influence\views.py", line 60, in event_attitude_statistics
    attitude_type = request.POST("attitude_type")
TypeError: 'QueryDict' object is not callable
2017-09-27 11:23:10,486 [Thread-4:10284] [django.request:256] [ERROR]- Internal Server Error: /sem_information/information_list_2/
Traceback (most recent call last):
  File "D:\python27\lib\site-packages\django\core\handlers\base.py", line 132, in get_response
    response = wrapped_callback(request, *callback_args, **callback_kwargs)
TypeError: information_list() takes exactly 1 argument (2 given)
2017-09-27 11:23:46,566 [Thread-2:15548] [django.request:170] [WARNING]- Not Found: /sem_information/information_list_2/
2017-09-27 11:23:52,493 [Thread-3:13732] [django.request:256] [ERROR]- Internal Server Error: /sem_information/information_list/
Traceback (most recent call last):
  File "D:\python27\lib\site-packages\django\core\handlers\base.py", line 132, in get_response
    response = wrapped_callback(request, *callback_args, **callback_kwargs)
  File "D:\zhujianwei\sem_analysis\sem_information\views.py", line 20, in information_list
    company_id = request.POST("company_id", -1)
TypeError: 'QueryDict' object is not callable
2017-09-27 11:24:34,891 [Thread-2:9912] [django.request:256] [ERROR]- Internal Server Error: /sem_information/information_list/
Traceback (most recent call last):
  File "D:\python27\lib\site-packages\django\core\handlers\base.py", line 132, in get_response
    response = wrapped_callback(request, *callback_args, **callback_kwargs)
  File "D:\zhujianwei\sem_analysis\sem_information\views.py", line 25, in information_list
    data_source_id_list = mysql_data.get_data_source_id_list(int(company_id), int(product_id), int(event_id))
  File "D:\zhujianwei\sem_analysis\common\mysql_data.py", line 8, in get_data_source_id_list
    cursor.execute(sql, relate_id)
  File "D:\python27\lib\site-packages\pymysql\cursors.py", line 164, in execute
    query = self.mogrify(query, args)
  File "D:\python27\lib\site-packages\pymysql\cursors.py", line 143, in mogrify
    query = query % self._escape_args(args, conn)
TypeError: not all arguments converted during string formatting
2017-09-27 13:40:42,269 [Thread-2:20492] [django.request:256] [ERROR]- Internal Server Error: /sem_information/information_detail_2/
Traceback (most recent call last):
  File "D:\python27\lib\site-packages\django\core\handlers\base.py", line 132, in get_response
    response = wrapped_callback(request, *callback_args, **callback_kwargs)
  File "D:\zhujianwei\sem_analysis\sem_information\views.py", line 43, in information_detail
    information_obj = source_media_instance_dict[media_source].get_object(ObjectId(information_id))
  File "D:\python27\lib\site-packages\bson\objectid.py", line 110, in __init__
    self.__validate(oid)
  File "D:\python27\lib\site-packages\bson\objectid.py", line 206, in __validate
    _raise_invalid_id(oid)
  File "D:\python27\lib\site-packages\bson\objectid.py", line 52, in _raise_invalid_id
    " or a 24-character hex string" % oid)
InvalidId: u'2' is not a valid ObjectId, it must be a 12-byte input or a 24-character hex string
2017-09-27 13:43:07,786 [Thread-2:540] [django.request:256] [ERROR]- Internal Server Error: /app_info/app_bangdan_info_2/
Traceback (most recent call last):
  File "D:\python27\lib\site-packages\django\core\handlers\base.py", line 132, in get_response
    response = wrapped_callback(request, *callback_args, **callback_kwargs)
  File "D:\zhujianwei\sem_analysis\app_info\views.py", line 21, in app_bangdan_info
    app_bangdan_info_obj = app_obj.get_app_bangdan_info_obj(data_source_id_list)
  File "D:\zhujianwei\sem_analysis\common\source_media.py", line 709, in get_app_bangdan_info_obj
    return serialize_news_obj(app_bangdan_info_obj)
  File "D:\zhujianwei\sem_analysis\common\common.py", line 55, in serialize_news_obj
    for item in news_obj:
  File "D:\python27\lib\site-packages\pymongo\cursor.py", line 1114, in next
    if len(self.__data) or self._refresh():
  File "D:\python27\lib\site-packages\pymongo\cursor.py", line 1036, in _refresh
    self.__collation))
  File "D:\python27\lib\site-packages\pymongo\cursor.py", line 928, in __send_message
    helpers._check_command_response(doc['data'][0])
  File "D:\python27\lib\site-packages\pymongo\helpers.py", line 210, in _check_command_response
    raise OperationFailure(msg % errmsg, code, response)
OperationFailure: $and/$or/$nor must be a nonempty array
2017-09-27 15:36:06,677 [Thread-2:2428] [django.request:170] [WARNING]- Not Found: /app_info/app_comment_info_2/
2017-09-28 11:28:44,201 [Thread-3:7676] [django.request:170] [WARNING]- Not Found: /favicon.ico
2017-09-29 09:27:23,025 [Thread-3:14284] [django.request:170] [WARNING]- Not Found: /favicon.ico
2017-10-10 16:24:29,323 [Thread-3:13256] [django.request:170] [WARNING]- Not Found: /favicon.ico
2017-10-10 16:48:41,756 [Thread-4:13480] [django.request:170] [WARNING]- Not Found: /sem_index/def today_sem_2/
2017-10-10 16:58:46,668 [Thread-8:5460] [django.request:256] [ERROR]- Internal Server Error: /sem_index/today_information_1/
Traceback (most recent call last):
  File "D:\python27\lib\site-packages\django\core\handlers\base.py", line 132, in get_response
    response = wrapped_callback(request, *callback_args, **callback_kwargs)
  File "D:\zhujianwei\sem_analysis\sem_index\views.py", line 105, in today_information
    data_source_id_list)["today_sort_news_objects"].clone().limit(10))
  File "D:\zhujianwei\sem_analysis\common\source_media.py", line 200, in get_sort_news_objects
    end_time=self.time_dict["now_time"])["sort_news_objects"],
  File "D:\zhujianwei\sem_analysis\common\source_media.py", line 280, in _get_news
    news_count = news_objects.count()
  File "D:\python27\lib\site-packages\pymongo\cursor.py", line 711, in count
    return self.__collection._count(cmd, self.__collation)
  File "D:\python27\lib\site-packages\pymongo\collection.py", line 1310, in _count
    collation=collation)
  File "D:\python27\lib\site-packages\pymongo\collection.py", line 232, in _command
    collation=collation)
  File "D:\python27\lib\site-packages\pymongo\pool.py", line 419, in command
    collation=collation)
  File "D:\python27\lib\site-packages\pymongo\network.py", line 116, in command
    parse_write_concern_error=parse_write_concern_error)
  File "D:\python27\lib\site-packages\pymongo\helpers.py", line 210, in _check_command_response
    raise OperationFailure(msg % errmsg, code, response)
OperationFailure: failed on : shard3RS
2017-10-10 17:51:11,444 [Thread-14:18136] [django.request:170] [WARNING]- Not Found: /product_influence/information_list_2/
2017-10-10 17:51:21,575 [Thread-16:18044] [django.request:170] [WARNING]- Not Found: /information_influence/information_list_2/
2017-10-10 17:51:35,536 [Thread-18:19376] [django.request:170] [WARNING]- Not Found: /sem_information/information_list_2/
2017-10-10 17:53:39,213 [Thread-22:8652] [django.request:256] [ERROR]- Internal Server Error: /sem_information/information_detail_2/
Traceback (most recent call last):
  File "D:\python27\lib\site-packages\django\core\handlers\base.py", line 132, in get_response
    response = wrapped_callback(request, *callback_args, **callback_kwargs)
TypeError: information_detail() takes exactly 3 arguments (2 given)
2017-10-10 17:57:34,857 [Thread-3:8380] [django.request:170] [WARNING]- Not Found: /sem_information/information_detail/
2017-10-10 17:58:02,892 [Thread-5:17828] [django.request:170] [WARNING]- Not Found: /sem_information/information_detail/
2017-10-10 17:58:05,210 [Thread-2:8168] [django.request:256] [ERROR]- Internal Server Error: /sem_information/information_detail/
Traceback (most recent call last):
  File "D:\python27\lib\site-packages\django\core\handlers\base.py", line 230, in get_response
    response = self.apply_response_fixes(request, response)
  File "D:\python27\lib\site-packages\django\core\handlers\base.py", line 277, in apply_response_fixes
    response = func(request, response)
  File "D:\python27\lib\site-packages\django\http\utils.py", line 30, in conditional_content_removal
    if 100 <= response.status_code < 200 or response.status_code in (204, 304):
AttributeError: 'dict' object has no attribute 'status_code'
2017-10-10 17:58:05,565 [Thread-3:13716] [django.request:256] [ERROR]- Internal Server Error: /sem_information/information_detail/
Traceback (most recent call last):
  File "D:\python27\lib\site-packages\django\core\handlers\base.py", line 230, in get_response
    response = self.apply_response_fixes(request, response)
  File "D:\python27\lib\site-packages\django\core\handlers\base.py", line 277, in apply_response_fixes
    response = func(request, response)
  File "D:\python27\lib\site-packages\django\http\utils.py", line 30, in conditional_content_removal
    if 100 <= response.status_code < 200 or response.status_code in (204, 304):
AttributeError: 'dict' object has no attribute 'status_code'
2017-10-10 17:58:59,589 [Thread-5:19068] [django.request:256] [ERROR]- Internal Server Error: /sem_information/information_detail/
Traceback (most recent call last):
  File "D:\python27\lib\site-packages\django\core\handlers\base.py", line 230, in get_response
    response = self.apply_response_fixes(request, response)
  File "D:\python27\lib\site-packages\django\core\handlers\base.py", line 277, in apply_response_fixes
    response = func(request, response)
  File "D:\python27\lib\site-packages\django\http\utils.py", line 30, in conditional_content_removal
    if 100 <= response.status_code < 200 or response.status_code in (204, 304):
AttributeError: 'dict' object has no attribute 'status_code'
2017-10-11 09:41:17,517 [Thread-2:17044] [django.request:170] [WARNING]- Not Found: /sem_information/information_detail_2/
2017-10-11 09:41:17,736 [Thread-3:16332] [django.request:170] [WARNING]- Not Found: /favicon.ico
2017-10-11 09:41:28,065 [Thread-4:9296] [django.request:256] [ERROR]- Internal Server Error: /sem_information/information_detail/
Traceback (most recent call last):
  File "D:\python27\lib\site-packages\django\core\handlers\base.py", line 230, in get_response
    response = self.apply_response_fixes(request, response)
  File "D:\python27\lib\site-packages\django\core\handlers\base.py", line 277, in apply_response_fixes
    response = func(request, response)
  File "D:\python27\lib\site-packages\django\http\utils.py", line 30, in conditional_content_removal
    if 100 <= response.status_code < 200 or response.status_code in (204, 304):
AttributeError: 'dict' object has no attribute 'status_code'
2017-10-11 09:41:52,845 [Thread-2:17104] [django.request:256] [ERROR]- Internal Server Error: /sem_information/information_detail/
Traceback (most recent call last):
  File "D:\python27\lib\site-packages\django\core\handlers\base.py", line 230, in get_response
    response = self.apply_response_fixes(request, response)
  File "D:\python27\lib\site-packages\django\core\handlers\base.py", line 277, in apply_response_fixes
    response = func(request, response)
  File "D:\python27\lib\site-packages\django\http\utils.py", line 30, in conditional_content_removal
    if 100 <= response.status_code < 200 or response.status_code in (204, 304):
AttributeError: 'dict' object has no attribute 'status_code'
2017-10-11 09:42:56,440 [Thread-2:3060] [django.request:256] [ERROR]- Internal Server Error: /sem_information/information_detail/
Traceback (most recent call last):
  File "D:\python27\lib\site-packages\django\core\handlers\base.py", line 230, in get_response
    response = self.apply_response_fixes(request, response)
  File "D:\python27\lib\site-packages\django\core\handlers\base.py", line 277, in apply_response_fixes
    response = func(request, response)
  File "D:\python27\lib\site-packages\django\http\utils.py", line 30, in conditional_content_removal
    if 100 <= response.status_code < 200 or response.status_code in (204, 304):
AttributeError: 'dict' object has no attribute 'status_code'
2017-10-11 09:43:19,430 [Thread-2:11116] [django.request:256] [ERROR]- Internal Server Error: /sem_information/information_detail/
Traceback (most recent call last):
  File "D:\python27\lib\site-packages\django\core\handlers\base.py", line 230, in get_response
    response = self.apply_response_fixes(request, response)
  File "D:\python27\lib\site-packages\django\core\handlers\base.py", line 277, in apply_response_fixes
    response = func(request, response)
  File "D:\python27\lib\site-packages\django\http\utils.py", line 30, in conditional_content_removal
    if 100 <= response.status_code < 200 or response.status_code in (204, 304):
AttributeError: 'dict' object has no attribute 'status_code'
2017-10-11 09:45:32,086 [Thread-2:11424] [django.request:256] [ERROR]- Internal Server Error: /sem_information/information_detail/
Traceback (most recent call last):
  File "D:\python27\lib\site-packages\django\core\handlers\base.py", line 230, in get_response
    response = self.apply_response_fixes(request, response)
  File "D:\python27\lib\site-packages\django\core\handlers\base.py", line 277, in apply_response_fixes
    response = func(request, response)
  File "D:\python27\lib\site-packages\django\http\utils.py", line 30, in conditional_content_removal
    if 100 <= response.status_code < 200 or response.status_code in (204, 304):
AttributeError: 'dict' object has no attribute 'status_code'
2017-10-11 09:45:52,378 [Thread-2:4696] [django.request:256] [ERROR]- Internal Server Error: /sem_information/information_detail/
Traceback (most recent call last):
  File "D:\python27\lib\site-packages\django\core\handlers\base.py", line 132, in get_response
    response = wrapped_callback(request, *callback_args, **callback_kwargs)
  File "D:\zhujianwei\sem_analysis\sem_information\views.py", line 48, in information_detail
    return JsonResponse(contents)
  File "D:\python27\lib\site-packages\django\http\response.py", line 535, in __init__
    data = json.dumps(data, cls=encoder)
  File "D:\python27\lib\json\__init__.py", line 251, in dumps
    sort_keys=sort_keys, **kw).encode(obj)
  File "D:\python27\lib\json\encoder.py", line 207, in encode
    chunks = self.iterencode(o, _one_shot=True)
  File "D:\python27\lib\json\encoder.py", line 270, in iterencode
    return _iterencode(o, 0)
  File "D:\python27\lib\site-packages\django\core\serializers\json.py", line 115, in default
    return super(DjangoJSONEncoder, self).default(o)
  File "D:\python27\lib\json\encoder.py", line 184, in default
    raise TypeError(repr(o) + " is not JSON serializable")
TypeError: <pymongo.cursor.Cursor object at 0x0000000004BA13C8> is not JSON serializable
2017-10-11 09:49:10,283 [Thread-4:2680] [django.request:256] [ERROR]- Internal Server Error: /app_info/app_comment_2/
Traceback (most recent call last):
  File "D:\python27\lib\site-packages\django\core\handlers\base.py", line 132, in get_response
    response = wrapped_callback(request, *callback_args, **callback_kwargs)
  File "D:\zhujianwei\sem_analysis\app_info\views.py", line 28, in app_comment
    app_comment_info = app_obj.get_app_comments_info(data_source_id_list)
  File "D:\zhujianwei\sem_analysis\common\source_media.py", line 676, in get_app_comments_info
    for obj in sort_comments_objects:
  File "D:\python27\lib\site-packages\pymongo\cursor.py", line 1114, in next
    if len(self.__data) or self._refresh():
  File "D:\python27\lib\site-packages\pymongo\cursor.py", line 1036, in _refresh
    self.__collation))
  File "D:\python27\lib\site-packages\pymongo\cursor.py", line 928, in __send_message
    helpers._check_command_response(doc['data'][0])
  File "D:\python27\lib\site-packages\pymongo\helpers.py", line 210, in _check_command_response
    raise OperationFailure(msg % errmsg, code, response)
OperationFailure: $and/$or/$nor must be a nonempty array
2017-10-11 09:53:55,128 [Thread-6:13024] [django.request:256] [ERROR]- Internal Server Error: /app_info/app_comment_3/
Traceback (most recent call last):
  File "D:\python27\lib\site-packages\django\core\handlers\base.py", line 132, in get_response
    response = wrapped_callback(request, *callback_args, **callback_kwargs)
  File "D:\zhujianwei\sem_analysis\app_info\views.py", line 28, in app_comment
    app_comment_info = app_obj.get_app_comments_info(data_source_id_list)
  File "D:\zhujianwei\sem_analysis\common\source_media.py", line 676, in get_app_comments_info
    for obj in sort_comments_objects:
  File "D:\python27\lib\site-packages\pymongo\cursor.py", line 1114, in next
    if len(self.__data) or self._refresh():
  File "D:\python27\lib\site-packages\pymongo\cursor.py", line 1036, in _refresh
    self.__collation))
  File "D:\python27\lib\site-packages\pymongo\cursor.py", line 928, in __send_message
    helpers._check_command_response(doc['data'][0])
  File "D:\python27\lib\site-packages\pymongo\helpers.py", line 210, in _check_command_response
    raise OperationFailure(msg % errmsg, code, response)
OperationFailure: $and/$or/$nor must be a nonempty array
2017-10-11 10:37:00,526 [Thread-2:10464] [django.request:256] [ERROR]- Internal Server Error: /app_info/app_comment_2/
Traceback (most recent call last):
  File "D:\python27\lib\site-packages\django\core\handlers\base.py", line 132, in get_response
    response = wrapped_callback(request, *callback_args, **callback_kwargs)
  File "D:\zhujianwei\sem_analysis\app_info\views.py", line 28, in app_comment
    app_comment_info = app_obj.get_app_comments_info(data_source_id_list)
  File "D:\zhujianwei\sem_analysis\common\source_media.py", line 686, in get_app_comments_info
    sentiment_obj_dict["positive_obj"].append(serialize_news_obj(obj))
  File "D:\zhujianwei\sem_analysis\common\common.py", line 60, in serialize_news_obj
    if item.get("_id"):
AttributeError: 'unicode' object has no attribute 'get'
2017-10-11 10:39:20,660 [Thread-2:3600] [django.request:256] [ERROR]- Internal Server Error: /app_info/app_comment_2/
Traceback (most recent call last):
  File "D:\python27\lib\site-packages\django\core\handlers\base.py", line 132, in get_response
    response = wrapped_callback(request, *callback_args, **callback_kwargs)
  File "D:\zhujianwei\sem_analysis\app_info\views.py", line 29, in app_comment
    return JsonResponse(app_comment_info)
  File "D:\python27\lib\site-packages\django\http\response.py", line 535, in __init__
    data = json.dumps(data, cls=encoder)
  File "D:\python27\lib\json\__init__.py", line 251, in dumps
    sort_keys=sort_keys, **kw).encode(obj)
  File "D:\python27\lib\json\encoder.py", line 207, in encode
    chunks = self.iterencode(o, _one_shot=True)
  File "D:\python27\lib\json\encoder.py", line 270, in iterencode
    return _iterencode(o, 0)
  File "D:\python27\lib\site-packages\django\core\serializers\json.py", line 115, in default
    return super(DjangoJSONEncoder, self).default(o)
  File "D:\python27\lib\json\encoder.py", line 184, in default
    raise TypeError(repr(o) + " is not JSON serializable")
TypeError: ObjectId('59dc6c39286fd49c3ed77e9f') is not JSON serializable
2017-10-11 10:42:05,006 [Thread-2:8844] [django.request:256] [ERROR]- Internal Server Error: /app_info/app_comment_2/
Traceback (most recent call last):
  File "D:\python27\lib\site-packages\django\core\handlers\base.py", line 132, in get_response
    response = wrapped_callback(request, *callback_args, **callback_kwargs)
  File "D:\zhujianwei\sem_analysis\app_info\views.py", line 28, in app_comment
    app_comment_info = app_obj.get_app_comments_info(data_source_id_list)
  File "D:\zhujianwei\sem_analysis\common\source_media.py", line 686, in get_app_comments_info
    sentiment_obj_dict["positive_obj"].append(serialize_news_obj(obj))
  File "D:\zhujianwei\sem_analysis\common\common.py", line 60, in serialize_news_obj
    if item.get("_id"):
AttributeError: 'unicode' object has no attribute 'get'
2017-10-11 10:43:48,954 [Thread-2:16764] [django.request:256] [ERROR]- Internal Server Error: /app_info/app_comment_2/
Traceback (most recent call last):
  File "D:\python27\lib\site-packages\django\core\handlers\base.py", line 132, in get_response
    response = wrapped_callback(request, *callback_args, **callback_kwargs)
  File "D:\zhujianwei\sem_analysis\app_info\views.py", line 28, in app_comment
    app_comment_info = app_obj.get_app_comments_info(data_source_id_list)
  File "D:\zhujianwei\sem_analysis\common\source_media.py", line 686, in get_app_comments_info
    sentiment_obj_dict["positive_obj"].append(serialize_news_obj(obj))
  File "D:\zhujianwei\sem_analysis\common\common.py", line 61, in serialize_news_obj
    if item.get("_id"):
AttributeError: 'unicode' object has no attribute 'get'
2017-10-11 10:44:55,076 [Thread-2:32] [django.request:256] [ERROR]- Internal Server Error: /app_info/app_comment_2/
Traceback (most recent call last):
  File "D:\python27\lib\site-packages\django\core\handlers\base.py", line 132, in get_response
    response = wrapped_callback(request, *callback_args, **callback_kwargs)
  File "D:\zhujianwei\sem_analysis\app_info\views.py", line 28, in app_comment
    app_comment_info = app_obj.get_app_comments_info(data_source_id_list)
  File "D:\zhujianwei\sem_analysis\common\source_media.py", line 687, in get_app_comments_info
    sentiment_obj_dict["positive_obj"].append(serialize_news_obj(obj))
  File "D:\zhujianwei\sem_analysis\common\common.py", line 61, in serialize_news_obj
    if item.get("_id"):
AttributeError: 'unicode' object has no attribute 'get'
2017-10-11 10:46:41,204 [Thread-2:14580] [django.request:170] [WARNING]- Not Found: /app_info/app_detail_2/
2017-10-11 10:48:24,770 [Thread-2:3640] [django.request:256] [ERROR]- Internal Server Error: /app_info/app_comment_2/
Traceback (most recent call last):
  File "D:\python27\lib\site-packages\django\core\handlers\base.py", line 132, in get_response
    response = wrapped_callback(request, *callback_args, **callback_kwargs)
  File "D:\zhujianwei\sem_analysis\app_info\views.py", line 28, in app_comment
    app_comment_info = app_obj.get_app_comments_info(data_source_id_list)
  File "D:\zhujianwei\sem_analysis\common\source_media.py", line 687, in get_app_comments_info
    sentiment_obj_dict["positive_obj"].append(serialize_news_obj(obj))
  File "D:\zhujianwei\sem_analysis\common\common.py", line 61, in serialize_news_obj
    if item.get("_id"):
AttributeError: 'unicode' object has no attribute 'get'
2017-10-11 14:10:33,490 [Thread-2:15972] [django.request:256] [ERROR]- Internal Server Error: /sem_information/information_detail/
Traceback (most recent call last):
  File "D:\python27\lib\site-packages\django\core\handlers\base.py", line 132, in get_response
    response = wrapped_callback(request, *callback_args, **callback_kwargs)
  File "D:\zhujianwei\sem_analysis\sem_information\views.py", line 52, in information_detail
    weibo_id = [obj.get("weibo_id") for obj in information_obj][0]
IndexError: list index out of range
2017-10-11 14:11:32,234 [Thread-2:7880] [django.request:256] [ERROR]- Internal Server Error: /sem_information/information_detail/
Traceback (most recent call last):
  File "D:\python27\lib\site-packages\django\core\handlers\base.py", line 132, in get_response
    response = wrapped_callback(request, *callback_args, **callback_kwargs)
  File "D:\zhujianwei\sem_analysis\sem_information\views.py", line 52, in information_detail
    weibo_id = [obj.get("weibo_id") for obj in information_obj][0]
IndexError: list index out of range
2017-10-11 14:26:46,647 [Thread-2:10676] [django.request:256] [ERROR]- Internal Server Error: /sem_information/information_detail/
Traceback (most recent call last):
  File "D:\python27\lib\site-packages\django\core\handlers\base.py", line 132, in get_response
    response = wrapped_callback(request, *callback_args, **callback_kwargs)
  File "D:\zhujianwei\sem_analysis\sem_information\views.py", line 65, in information_detail
    contents["reply_obj"] = sort_rely_obj[0]
TypeError: 'NoneType' object has no attribute '__getitem__'
2017-10-11 14:28:44,000 [Thread-2:7468] [django.request:256] [ERROR]- Internal Server Error: /sem_information/information_detail/
Traceback (most recent call last):
  File "D:\python27\lib\site-packages\django\core\handlers\base.py", line 132, in get_response
    response = wrapped_callback(request, *callback_args, **callback_kwargs)
  File "D:\zhujianwei\sem_analysis\sem_information\views.py", line 66, in information_detail
    contents["reply_obj"] = sort_rely_obj[0]
TypeError: 'NoneType' object has no attribute '__getitem__'
2017-10-11 14:30:35,358 [Thread-2:14768] [django.request:256] [ERROR]- Internal Server Error: /sem_information/information_detail/
Traceback (most recent call last):
  File "D:\python27\lib\site-packages\django\core\handlers\base.py", line 132, in get_response
    response = wrapped_callback(request, *callback_args, **callback_kwargs)
  File "D:\zhujianwei\sem_analysis\sem_information\views.py", line 67, in information_detail
    contents["reply_obj"] = sort_rely_obj[0]
TypeError: 'NoneType' object has no attribute '__getitem__'
2017-10-11 14:31:37,286 [Thread-2:11404] [django.request:256] [ERROR]- Internal Server Error: /sem_information/information_detail/
Traceback (most recent call last):
  File "D:\python27\lib\site-packages\django\core\handlers\base.py", line 132, in get_response
    response = wrapped_callback(request, *callback_args, **callback_kwargs)
  File "D:\zhujianwei\sem_analysis\sem_information\views.py", line 67, in information_detail
    contents["reply_obj"] = sort_rely_obj[0]
TypeError: 'NoneType' object has no attribute '__getitem__'
2017-10-11 14:32:33,644 [Thread-2:15988] [django.request:256] [ERROR]- Internal Server Error: /sem_information/information_detail/
Traceback (most recent call last):
  File "D:\python27\lib\site-packages\django\core\handlers\base.py", line 132, in get_response
    response = wrapped_callback(request, *callback_args, **callback_kwargs)
  File "D:\zhujianwei\sem_analysis\sem_information\views.py", line 66, in information_detail
    contents["reply_obj"] = reply_obj_list[0]
IndexError: list index out of range
2017-10-12 17:15:02,802 [Thread-3:8016] [django.request:170] [WARNING]- Not Found: /favicon.ico
2017-10-13 15:13:06,234 [Thread-8:14728] [django.request:170] [WARNING]- Not Found: /favicon.ico
2017-10-13 16:29:16,996 [Thread-3:12264] [django.request:170] [WARNING]- Not Found: /admin/sem_index/adminuserinfo/1/
2017-10-13 16:35:02,753 [Thread-7:18776] [django.request:170] [WARNING]- Not Found: /
2017-10-16 14:00:56,378 [Thread-3:10088] [django.request:170] [WARNING]- Not Found: /favicon.ico
2017-10-16 14:14:11,246 [Thread-40:19244] [django.request:170] [WARNING]- Not Found: /
2017-10-17 10:18:21,959 [Thread-3:15880] [django.request:170] [WARNING]- Not Found: /favicon.ico
2017-10-17 17:06:33,992 [Thread-3:13724] [django.request:170] [WARNING]- Not Found: /favicon.ico
2017-10-17 17:07:20,795 [Thread-3:10936] [django.request:256] [ERROR]- Internal Server Error: /admin/sem_index/datasourceid/
Traceback (most recent call last):
  File "D:\python27\lib\site-packages\django\core\handlers\base.py", line 132, in get_response
    response = wrapped_callback(request, *callback_args, **callback_kwargs)
  File "D:\python27\lib\site-packages\django\contrib\admin\options.py", line 618, in wrapper
    return self.admin_site.admin_view(view)(*args, **kwargs)
  File "D:\python27\lib\site-packages\django\utils\decorators.py", line 110, in _wrapped_view
    response = view_func(request, *args, **kwargs)
  File "D:\python27\lib\site-packages\django\views\decorators\cache.py", line 57, in _wrapped_view_func
    response = view_func(request, *args, **kwargs)
  File "D:\python27\lib\site-packages\django\contrib\admin\sites.py", line 233, in inner
    return view(request, *args, **kwargs)
  File "D:\python27\lib\site-packages\django\utils\decorators.py", line 34, in _wrapper
    return bound_func(*args, **kwargs)
  File "D:\python27\lib\site-packages\django\utils\decorators.py", line 110, in _wrapped_view
    response = view_func(request, *args, **kwargs)
  File "D:\python27\lib\site-packages\django\utils\decorators.py", line 30, in bound_func
    return func.__get__(self, type(self))(*args2, **kwargs2)
  File "D:\python27\lib\site-packages\django\contrib\admin\options.py", line 1550, in changelist_view
    self.list_max_show_all, self.list_editable, self)
  File "D:\python27\lib\site-packages\django\contrib\admin\views\main.py", line 82, in __init__
    self.get_results(request)
  File "D:\python27\lib\site-packages\django\contrib\admin\views\main.py", line 177, in get_results
    result_count = paginator.count
  File "D:\python27\lib\site-packages\django\core\paginator.py", line 72, in _get_count
    self._count = self.object_list.count()
  File "D:\python27\lib\site-packages\django\db\models\query.py", line 318, in count
    return self.query.get_count(using=self.db)
  File "D:\python27\lib\site-packages\django\db\models\sql\query.py", line 466, in get_count
    number = obj.get_aggregation(using, ['__count'])['__count']
  File "D:\python27\lib\site-packages\django\db\models\sql\query.py", line 447, in get_aggregation
    result = compiler.execute_sql(SINGLE)
  File "D:\python27\lib\site-packages\django\db\models\sql\compiler.py", line 840, in execute_sql
    cursor.execute(sql, params)
  File "D:\python27\lib\site-packages\django\db\backends\utils.py", line 79, in execute
    return super(CursorDebugWrapper, self).execute(sql, params)
  File "D:\python27\lib\site-packages\django\db\backends\utils.py", line 64, in execute
    return self.cursor.execute(sql, params)
  File "D:\python27\lib\site-packages\django\db\utils.py", line 98, in __exit__
    six.reraise(dj_exc_type, dj_exc_value, traceback)
  File "D:\python27\lib\site-packages\django\db\backends\utils.py", line 64, in execute
    return self.cursor.execute(sql, params)
  File "D:\python27\lib\site-packages\django\db\backends\mysql\base.py", line 124, in execute
    return self.cursor.execute(query, args)
  File "D:\python27\lib\site-packages\MySQLdb\cursors.py", line 174, in execute
    self.errorhandler(self, exc, value)
  File "D:\python27\lib\site-packages\MySQLdb\connections.py", line 36, in defaulterrorhandler
    raise errorclass, errorvalue
ProgrammingError: (1146, "Table 'sem_analysis.sem_monitor_crawl_info' doesn't exist")
2017-10-17 17:07:34,871 [Thread-8:8208] [django.request:256] [ERROR]- Internal Server Error: /admin/sem_index/datasourceid/
Traceback (most recent call last):
  File "D:\python27\lib\site-packages\django\core\handlers\base.py", line 132, in get_response
    response = wrapped_callback(request, *callback_args, **callback_kwargs)
  File "D:\python27\lib\site-packages\django\contrib\admin\options.py", line 618, in wrapper
    return self.admin_site.admin_view(view)(*args, **kwargs)
  File "D:\python27\lib\site-packages\django\utils\decorators.py", line 110, in _wrapped_view
    response = view_func(request, *args, **kwargs)
  File "D:\python27\lib\site-packages\django\views\decorators\cache.py", line 57, in _wrapped_view_func
    response = view_func(request, *args, **kwargs)
  File "D:\python27\lib\site-packages\django\contrib\admin\sites.py", line 233, in inner
    return view(request, *args, **kwargs)
  File "D:\python27\lib\site-packages\django\utils\decorators.py", line 34, in _wrapper
    return bound_func(*args, **kwargs)
  File "D:\python27\lib\site-packages\django\utils\decorators.py", line 110, in _wrapped_view
    response = view_func(request, *args, **kwargs)
  File "D:\python27\lib\site-packages\django\utils\decorators.py", line 30, in bound_func
    return func.__get__(self, type(self))(*args2, **kwargs2)
  File "D:\python27\lib\site-packages\django\contrib\admin\options.py", line 1550, in changelist_view
    self.list_max_show_all, self.list_editable, self)
  File "D:\python27\lib\site-packages\django\contrib\admin\views\main.py", line 82, in __init__
    self.get_results(request)
  File "D:\python27\lib\site-packages\django\contrib\admin\views\main.py", line 177, in get_results
    result_count = paginator.count
  File "D:\python27\lib\site-packages\django\core\paginator.py", line 72, in _get_count
    self._count = self.object_list.count()
  File "D:\python27\lib\site-packages\django\db\models\query.py", line 318, in count
    return self.query.get_count(using=self.db)
  File "D:\python27\lib\site-packages\django\db\models\sql\query.py", line 466, in get_count
    number = obj.get_aggregation(using, ['__count'])['__count']
  File "D:\python27\lib\site-packages\django\db\models\sql\query.py", line 447, in get_aggregation
    result = compiler.execute_sql(SINGLE)
  File "D:\python27\lib\site-packages\django\db\models\sql\compiler.py", line 840, in execute_sql
    cursor.execute(sql, params)
  File "D:\python27\lib\site-packages\django\db\backends\utils.py", line 79, in execute
    return super(CursorDebugWrapper, self).execute(sql, params)
  File "D:\python27\lib\site-packages\django\db\backends\utils.py", line 64, in execute
    return self.cursor.execute(sql, params)
  File "D:\python27\lib\site-packages\django\db\utils.py", line 98, in __exit__
    six.reraise(dj_exc_type, dj_exc_value, traceback)
  File "D:\python27\lib\site-packages\django\db\backends\utils.py", line 64, in execute
    return self.cursor.execute(sql, params)
  File "D:\python27\lib\site-packages\django\db\backends\mysql\base.py", line 124, in execute
    return self.cursor.execute(query, args)
  File "D:\python27\lib\site-packages\MySQLdb\cursors.py", line 174, in execute
    self.errorhandler(self, exc, value)
  File "D:\python27\lib\site-packages\MySQLdb\connections.py", line 36, in defaulterrorhandler
    raise errorclass, errorvalue
ProgrammingError: (1146, "Table 'sem_analysis.sem_monitor_crawl_info' doesn't exist")
2017-10-18 09:25:15,961 [Thread-4:8984] [django.request:170] [WARNING]- Not Found: /favicon.ico
2017-10-18 10:08:57,394 [Thread-2:20688] [django.request:256] [ERROR]- Internal Server Error: /sem_index/weibo_2/
Traceback (most recent call last):
  File "D:\python27\lib\site-packages\django\core\handlers\base.py", line 132, in get_response
    response = wrapped_callback(request, *callback_args, **callback_kwargs)
  File "D:\github\sem_analysis\sem_index\views.py", line 121, in weibo
    weibo_obj = weibo_instance.get_sort_news_objects(data_source_id_list)["today_sort_news_objects"].clone().limit(10)
  File "D:\github\sem_analysis\common\source_media.py", line 200, in get_sort_news_objects
    end_time=self.time_dict["now_time"])["sort_news_objects"],
  File "D:\github\sem_analysis\common\source_media.py", line 483, in _get_news
    news_count = news_objects.count()
  File "D:\python27\lib\site-packages\pymongo\cursor.py", line 711, in count
    return self.__collection._count(cmd, self.__collation)
  File "D:\python27\lib\site-packages\pymongo\collection.py", line 1310, in _count
    collation=collation)
  File "D:\python27\lib\site-packages\pymongo\collection.py", line 232, in _command
    collation=collation)
  File "D:\python27\lib\site-packages\pymongo\pool.py", line 419, in command
    collation=collation)
  File "D:\python27\lib\site-packages\pymongo\network.py", line 116, in command
    parse_write_concern_error=parse_write_concern_error)
  File "D:\python27\lib\site-packages\pymongo\helpers.py", line 210, in _check_command_response
    raise OperationFailure(msg % errmsg, code, response)
OperationFailure: failed on : shard3RS
2017-10-18 10:37:35,970 [Thread-4:14848] [django.request:256] [ERROR]- Internal Server Error: /sem_index/weibo_1/
Traceback (most recent call last):
  File "D:\python27\lib\site-packages\django\core\handlers\base.py", line 132, in get_response
    response = wrapped_callback(request, *callback_args, **callback_kwargs)
  File "D:\github\sem_analysis\sem_index\views.py", line 126, in weibo
    weibo_obj = weibo_instance.get_sort_news_objects(data_source_id_list)["today_sort_news_objects"].clone().limit(10)
  File "D:\github\sem_analysis\common\source_media.py", line 200, in get_sort_news_objects
    end_time=self.time_dict["now_time"])["sort_news_objects"],
  File "D:\github\sem_analysis\common\source_media.py", line 483, in _get_news
    news_count = news_objects.count()
  File "D:\python27\lib\site-packages\pymongo\cursor.py", line 711, in count
    return self.__collection._count(cmd, self.__collation)
  File "D:\python27\lib\site-packages\pymongo\collection.py", line 1310, in _count
    collation=collation)
  File "D:\python27\lib\site-packages\pymongo\collection.py", line 232, in _command
    collation=collation)
  File "D:\python27\lib\site-packages\pymongo\pool.py", line 424, in command
    self._raise_connection_failure(error)
  File "D:\python27\lib\site-packages\pymongo\pool.py", line 552, in _raise_connection_failure
    raise error
InvalidDocument: Cannot encode object: <SemMonitorCrawlInfo: 鑵捐绉戞妧>
2017-10-18 10:51:26,240 [Thread-2:12676] [django.request:256] [ERROR]- Internal Server Error: /sem_index/weibo_1/
Traceback (most recent call last):
  File "D:\python27\lib\site-packages\django\core\handlers\base.py", line 132, in get_response
    response = wrapped_callback(request, *callback_args, **callback_kwargs)
  File "D:\github\sem_analysis\sem_index\views.py", line 128, in weibo
    weibo_obj = weibo_instance.get_sort_news_objects(data_source_id_list)["today_sort_news_objects"].clone().limit(10)
  File "D:\github\sem_analysis\common\source_media.py", line 200, in get_sort_news_objects
    end_time=self.time_dict["now_time"])["sort_news_objects"],
  File "D:\github\sem_analysis\common\source_media.py", line 483, in _get_news
    news_count = news_objects.count()
  File "D:\python27\lib\site-packages\pymongo\cursor.py", line 711, in count
    return self.__collection._count(cmd, self.__collation)
  File "D:\python27\lib\site-packages\pymongo\collection.py", line 1310, in _count
    collation=collation)
  File "D:\python27\lib\site-packages\pymongo\collection.py", line 232, in _command
    collation=collation)
  File "D:\python27\lib\site-packages\pymongo\pool.py", line 424, in command
    self._raise_connection_failure(error)
  File "D:\python27\lib\site-packages\pymongo\pool.py", line 552, in _raise_connection_failure
    raise error
InvalidDocument: Cannot encode object: <SemMonitorCrawlInfo: 腾讯科技>
2017-10-18 10:55:59,424 [Thread-2:4904] [django.request:256] [ERROR]- Internal Server Error: /sem_index/weibo_1/
Traceback (most recent call last):
  File "D:\python27\lib\site-packages\django\core\handlers\base.py", line 132, in get_response
    response = wrapped_callback(request, *callback_args, **callback_kwargs)
  File "D:\github\sem_analysis\sem_index\views.py", line 121, in weibo
    if len(data_source_id_list) > 0:
TypeError: object of type 'NoneType' has no len()
2017-10-19 15:10:32,486 [Thread-4:11364] [django.request:170] [WARNING]- Not Found: /favicon.ico
2017-10-20 09:28:34,928 [Thread-9:17800] [django.request:170] [WARNING]- Not Found: /favicon.ico
2017-10-20 09:51:53,855 [Thread-2:14308] [django.request:170] [WARNING]- Not Found: /sem_index/
2017-10-20 10:50:43,434 [Thread-5:16368] [django.request:170] [WARNING]- Not Found: /sem_index/influence_show/2/influence_directive
2017-10-20 10:50:51,671 [Thread-6:18832] [django.request:170] [WARNING]- Not Found: /sem_index/today_hot_2/
